Workbook

Sheet 詳細查詢
A1: =left(A13,2) -> 綠色 | C1: =left(C13,2) | E1: =left(E13,2)
H2: =IFERROR(__xludf.DUMMYFUNCTION("IF(B3="""", '寶可夢喜好表'!B2:B330, FILTER('寶可夢喜好表'!B2:B330, ISNUMBER(SEARCH(B3, '寶可夢喜好表'!B2:B330))))"),"小火龍") -> 小火龍 | I2: 20160321
A3: 手輸專長 | B3: 火 | H3: =IFERROR(__xludf.DUMMYFUNCTION("""COMPUTED_VALUE"""),"火恐龍") -> 火恐龍
A4: 點火 | B4: 小火龍 | H4: =IFERROR(__xludf.DUMMYFUNCTION("""COMPUTED_VALUE"""),"噴火龍") -> 噴火龍
H5: =IFERROR(__xludf.DUMMYFUNCTION("""COMPUTED_VALUE"""),"燈火幽靈") -> 燈火幽靈
A6: 專長 | B6: 喜歡的環境 | C6: 喜歡的事物 | D6: 喜歡的口味 (範例) | H6: =IFERROR(__xludf.DUMMYFUNCTION("""COMPUTED_VALUE"""),"水晶燈火靈") -> 水晶燈火靈
A7: {=XLOOKUP(B4, '寶可夢喜好表'!B:B, '寶可夢喜好表'!C:C, "尚無專長資料")} -> 點火 | B7: {=XLOOKUP(B4, '寶可夢喜好表'!B:B, '寶可夢喜好表'!E:E, "尚無棲息地資料")} -> 溫暖 | C7: {=XLOOKUP(B4, '寶可夢喜好表'!B:B, '寶可夢喜好表'!F:F, "尚無棲息地資料")} -> 感受火焰、木製、堅硬、訓練、大家一起用 | D7: {=XLOOKUP(B4, '寶可夢喜好表'!B:B, '寶可夢喜好表'!G:G, "尚無棲息地資料")} -> 辣 (紅蘿蔔) | H7: =IFERROR(__xludf.DUMMYFUNCTION("""COMPUTED_VALUE"""),"火雉雞") -> 火雉雞
H8: =IFERROR(__xludf.DUMMYFUNCTION("""COMPUTED_VALUE"""),"火焰雞") -> 火焰雞
A9: 掉落物 | H9: =IFERROR(__xludf.DUMMYFUNCTION("""COMPUTED_VALUE"""),"鴨嘴火獸") -> 鴨嘴火獸
A10: {=XLOOKUP(B4, '寶可夢喜好表'!B:B, '寶可夢喜好表'!D:D, "尚無棲息地資料")} | H10: =IFERROR(__xludf.DUMMYFUNCTION("""COMPUTED_VALUE"""),"火神蛾") -> 火神蛾
H11: =IFERROR(__xludf.DUMMYFUNCTION("""COMPUTED_VALUE"""),"火球鼠") -> 火球鼠
A12: 棲息地1 / 道具) | B12: 寶可夢 | C12: 棲息地2/ 道具) | D12: 寶可夢 | E12: 棲息地3 / 道具) | F12: 寶可夢 | H12: =IFERROR(__xludf.DUMMYFUNCTION("""COMPUTED_VALUE"""),"火岩鼠") -> 火岩鼠
A13: {=XLOOKUP(B4, '寶可夢喜好表'!B:B, '寶可夢喜好表'!H:H, "尚無棲息地資料")} -> 綠色的草叢 / 綠草 ×4 | B13: {=XLOOKUP(B4, '寶可夢喜好表'!B:B, '寶可夢喜好表'!I:I, "尚無棲息地資料")} -> 妙蛙種子、小火龍、噴火龍、傑尼龜、走路草、小拳石（空空鎮) | C13: {=XLOOKUP(B4, '寶可夢喜好表'!B:B, '寶可夢喜好表'!J:J, "尚無棲息地資料")} | D13: {=XLOOKUP(B4, '寶可夢喜好表'!B:B, '寶可夢喜好表'!K:K, "尚無棲息地資料")} | E13: {=XLOOKUP(B4, '寶可夢喜好表'!B:B, '寶可夢喜好表'!L:L, "尚無棲息地資料")} | F13: {=XLOOKUP(B4, '寶可夢喜好表'!B:B, '寶可夢喜好表'!M:M, "尚無棲息地資料")} | H13: =IFERROR(__xludf.DUMMYFUNCTION("""COMPUTED_VALUE"""),"火爆獸") -> 火爆獸
A14: {=IF(A1="", "", IFERROR(IMAGE(XLOOKUP("*" & TRIM(A1) & "*", '棲息地'!$B:$B, '棲息地'!$F:$F, "找不到圖片", 2), 1), ""))} | C14: {=IF(C1="", "", IFERROR(IMAGE(XLOOKUP("*" & TRIM(C1) & "*", '棲息地'!$B:$B, '棲息地'!$F:$F, "找不到圖片", 2), 1), ""))} | E14: {=IF(E1="", "", IFERROR(IMAGE(XLOOKUP("*" & TRIM(E1) & "*", '棲息地'!$B:$B, '棲息地'!$F:$F, "找不到圖片", 2), 1), ""))} | G14: =IFERROR(__xludf.DUMMYFUNCTION("IF(A4="""", ""請先在 A3 輸入或選擇專長"", IFERROR(FILTER('寶可夢喜好表'!B:B, '寶可夢喜好表'!C:C=A4), ""查無此專長""))"),"小火龍") -> 小火龍 | H14: =IFERROR(__xludf.DUMMYFUNCTION("""COMPUTED_VALUE"""),"火伊布") -> 火伊布
G15: =IFERROR(__xludf.DUMMYFUNCTION("""COMPUTED_VALUE"""),"火恐龍") -> 火恐龍 | H15: =IFERROR(__xludf.DUMMYFUNCTION("""COMPUTED_VALUE"""),"火焰鳥") -> 火焰鳥
G16: =IFERROR(__xludf.DUMMYFUNCTION("""COMPUTED_VALUE"""),"燭光靈") -> 燭光靈
G17: =IFERROR(__xludf.DUMMYFUNCTION("""COMPUTED_VALUE"""),"燈火幽靈") -> 燈火幽靈
G18: =IFERROR(__xludf.DUMMYFUNCTION("""COMPUTED_VALUE"""),"水晶燈火靈") -> 水晶燈火靈
G19: =IFERROR(__xludf.DUMMYFUNCTION("""COMPUTED_VALUE"""),"火雉雞") -> 火雉雞
G20: =IFERROR(__xludf.DUMMYFUNCTION("""COMPUTED_VALUE"""),"鴨嘴寶寶") -> 鴨嘴寶寶
G21: =IFERROR(__xludf.DUMMYFUNCTION("""COMPUTED_VALUE"""),"鴨嘴火獸") -> 鴨嘴火獸
G22: =IFERROR(__xludf.DUMMYFUNCTION("""COMPUTED_VALUE"""),"煤炭龜") -> 煤炭龜
G23: =IFERROR(__xludf.DUMMYFUNCTION("""COMPUTED_VALUE"""),"炎兔兒") -> 炎兔兒
G24: =IFERROR(__xludf.DUMMYFUNCTION("""COMPUTED_VALUE"""),"騰蹴小將") -> 騰蹴小將
G25: =IFERROR(__xludf.DUMMYFUNCTION("""COMPUTED_VALUE"""),"炭小侍") -> 炭小侍
G26: =IFERROR(__xludf.DUMMYFUNCTION("""COMPUTED_VALUE"""),"六尾") -> 六尾
G27: =IFERROR(__xludf.DUMMYFUNCTION("""COMPUTED_VALUE"""),"九尾") -> 九尾
G28: =IFERROR(__xludf.DUMMYFUNCTION("""COMPUTED_VALUE"""),"火球鼠") -> 火球鼠
G29: =IFERROR(__xludf.DUMMYFUNCTION("""COMPUTED_VALUE"""),"火岩鼠") -> 火岩鼠
G30: =IFERROR(__xludf.DUMMYFUNCTION("""COMPUTED_VALUE"""),"火伊布") -> 火伊布
G31: =IFERROR(__xludf.DUMMYFUNCTION("""COMPUTED_VALUE"""),"炎帝") -> 炎帝
G32: =IFERROR(__xludf.DUMMYFUNCTION("""COMPUTED_VALUE"""),"波爾凱尼恩") -> 波爾凱尼恩

Sheet 棲息地
A1: 編號 | B1: 棲息地名稱 | C1: 核心道具需求 | D1: 出現寶可夢
A2: No.001 | B2: 綠色的草叢 | C2: 綠草 ×4 | D2: 妙蛙種子、小火龍、噴火龍、傑尼龜、走路草、小拳石（空空鎮) | E2: https://drive.google.com/file/d/1Zui1QKajr4K54-QnVN11axFwFdXqil_m/view?usp=drive_link | F2: =IFERROR(__xludf.DUMMYFUNCTION("IF(E2="""", """", ""https://drive.google.com/uc?export=view&id="" & REGEXEXTRACT(E2, ""/d/(.*)/""))"),"https://drive.google.com/uc?export=view&id=1Zui1QKajr4K54-QnVN11axFwFdXqil_m") -> https://drive.google.com/uc?export=view&id=1Zui1QKajr4K54-QnVN11axFwFdXqil_m
A3: No.002 | B3: 樹蔭的草叢 | C3: 大樹 ×1、綠草 ×4 | D3: 飛天螳螂、喇叭芽、巨鉗螳螂（空空鎮)、赫拉克羅斯、凱羅斯、貪心栗鼠（空空鎮) | E3: https://drive.google.com/file/d/19CrdN30HGmpE_sHBpHI0ykoC1Xzs3nFL/view?usp=drive_link | F3: =IFERROR(__xludf.DUMMYFUNCTION("IF(E3="""", """", ""https://drive.google.com/uc?export=view&id="" & REGEXEXTRACT(E3, ""/d/(.*)/""))"),"https://drive.google.com/uc?export=view&id=19CrdN30HGmpE_sHBpHI0ykoC1Xzs3nFL") -> https://drive.google.com/uc?export=view&id=19CrdN30HGmpE_sHBpHI0ykoC1Xzs3nFL
A4: No.003 | B4: 岩影的草地 | C4: 綠草 ×4、大石頭 ×1 | D4: 搬運小匠、鐵骨土人、腕力（空空鎮) | E4: https://drive.google.com/file/d/1ELHxpsZlcq5M83YhnRXD5C6FIN78pF-b/view?usp=drive_link | F4: =IFERROR(__xludf.DUMMYFUNCTION("IF(E4="""", """", ""https://drive.google.com/uc?export=view&id="" & REGEXEXTRACT(E4, ""/d/(.*)/""))"),"https://drive.google.com/uc?export=view&id=1ELHxpsZlcq5M83YhnRXD5C6FIN78pF-b") -> https://drive.google.com/uc?export=view&id=1ELHxpsZlcq5M83YhnRXD5C6FIN78pF-b
A5: No.004 | B5: 濕潤的草地 | C5: 綠草 ×4、水 ×2 | D5: 傑尼龜、卡咪龜、水箭龜、黏美兒、古月鳥（空空鎮) | E5: https://drive.google.com/file/d/1fwTkKzuuQxM9eaQ9Ln-6BPQEbC_bwkjJ/view?usp=drive_link | F5: =IFERROR(__xludf.DUMMYFUNCTION("IF(E5="""", """", ""https://drive.google.com/uc?export=view&id="" & REGEXEXTRACT(E5, ""/d/(.*)/""))"),"https://drive.google.com/uc?export=view&id=1fwTkKzuuQxM9eaQ9Ln-6BPQEbC_bwkjJ") -> https://drive.google.com/uc?export=view&id=1fwTkKzuuQxM9eaQ9Ln-6BPQEbC_bwkjJ
A6: No.005 | B6: 海浪邊的草叢 | C6: 綠草 ×4、海水 ×2 | D6: 呆呆獸、呆呆王、呆殼獸 | E6: https://drive.google.com/file/d/1zKMMiq7r3vrF5UvmbZPtVtD_dfDYdUP3/view?usp=drive_link | F6: =IFERROR(__xludf.DUMMYFUNCTION("IF(E6="""", """", ""https://drive.google.com/uc?export=view&id="" & REGEXEXTRACT(E6, ""/d/(.*)/""))"),"https://drive.google.com/uc?export=view&id=1zKMMiq7r3vrF5UvmbZPtVtD_dfDYdUP3") -> https://drive.google.com/uc?export=view&id=1zKMMiq7r3vrF5UvmbZPtVtD_dfDYdUP3
A7: No.006 | B7: 高崗的草叢 | C7: 綠草 ×4、高處 ×1 | D7: 咕咕、波波、比比鳥 | E7: https://drive.google.com/file/d/1Z5rKeD-bOwEO2zJCMhi8LMhShYWp-Ddb/view?usp=drive_link | F7: =IFERROR(__xludf.DUMMYFUNCTION("IF(E7="""", """", ""https://drive.google.com/uc?export=view&id="" & REGEXEXTRACT(E7, ""/d/(.*)/""))"),"https://drive.google.com/uc?export=view&id=1Z5rKeD-bOwEO2zJCMhi8LMhShYWp-Ddb") -> https://drive.google.com/uc?export=view&id=1Z5rKeD-bOwEO2zJCMhi8LMhShYWp-Ddb
A8: No.007 | B8: 光照的草叢 | C8: 草叢(任意) ×4、照明(任意) ×1 | D8: 毛球、摩魯蛾 | E8: https://drive.google.com/file/d/1t8xnCYn4TFB4oYGXSu-SqsGqdBDu9QAV/view?usp=drive_link | F8: =IFERROR(__xludf.DUMMYFUNCTION("IF(E8="""", """", ""https://drive.google.com/uc?export=view&id="" & REGEXEXTRACT(E8, ""/d/(.*)/""))"),"https://drive.google.com/uc?export=view&id=1t8xnCYn4TFB4oYGXSu-SqsGqdBDu9QAV") -> https://drive.google.com/uc?export=view&id=1t8xnCYn4TFB4oYGXSu-SqsGqdBDu9QAV
A9: No.008 | B9: 漂亮的花田 | C9: 原野之花 ×4 | D9: 咕咕、三蜜蜂、伊布、波波（空空鎮)、鴨嘴寶寶（空空鎮) | E9: https://drive.google.com/file/d/1fZ5xoeCppudNCNreKNTA1N9jUYmH0NvG/view?usp=drive_link | F9: =IFERROR(__xludf.DUMMYFUNCTION("IF(E9="""", """", ""https://drive.google.com/uc?export=view&id="" & REGEXEXTRACT(E9, ""/d/(.*)/""))"),"https://drive.google.com/uc?export=view&id=1fZ5xoeCppudNCNreKNTA1N9jUYmH0NvG") -> https://drive.google.com/uc?export=view&id=1fZ5xoeCppudNCNreKNTA1N9jUYmH0NvG
A10: No.009 | B10: 樹蔭的花田 | C10: 原野之花 ×4 | D10: 黏黏寶、夢歌仙人掌、鍬農炮蟲（空空鎮) | E10: https://drive.google.com/file/d/1Pa_OwADXdwfpOXBTrfLWXVTRGQROALa4/view?usp=drive_link | F10: =IFERROR(__xludf.DUMMYFUNCTION("IF(E10="""", """", ""https://drive.google.com/uc?export=view&id="" & REGEXEXTRACT(E10, ""/d/(.*)/""))"),"https://drive.google.com/uc?export=view&id=1Pa_OwADXdwfpOXBTrfLWXVTRGQROALa4") -> https://drive.google.com/uc?export=view&id=1Pa_OwADXdwfpOXBTrfLWXVTRGQROALa4
A11: No.010 | B11: 濕潤的花田 | C11: 原野之花 ×4、水 ×2 | D11: 甜甜螢、電螢蟲 | E11: https://drive.google.com/file/d/13GWQEZZL6FlM4c33is_47k5pEQD6fHjB/view?usp=drive_link | F11: =IFERROR(__xludf.DUMMYFUNCTION("IF(E11="""", """", ""https://drive.google.com/uc?export=view&id="" & REGEXEXTRACT(E11, ""/d/(.*)/""))"),"https://drive.google.com/uc?export=view&id=13GWQEZZL6FlM4c33is_47k5pEQD6fHjB") -> https://drive.google.com/uc?export=view&id=13GWQEZZL6FlM4c33is_47k5pEQD6fHjB
A12: No.011 | B12: 整片的花海 | C12: 原野之花 ×8 | D12: 妙蛙草、妙蛙花、蜂女王 | E12: https://drive.google.com/file/d/1fBC42KzrWPHrGrKZSlsuPGUcffl2FbPM/view?usp=drive_link | F12: =IFERROR(__xludf.DUMMYFUNCTION("IF(E12="""", """", ""https://drive.google.com/uc?export=view&id="" & REGEXEXTRACT(E12, ""/d/(.*)/""))"),"https://drive.google.com/uc?export=view&id=1fBC42KzrWPHrGrKZSlsuPGUcffl2FbPM") -> https://drive.google.com/uc?export=view&id=1fBC42KzrWPHrGrKZSlsuPGUcffl2FbPM
A13: No.012 | B13: 高崗的花海 | C13: 原野之花 ×4、高處 ×1 | D13: 派拉斯、派拉斯特 | E13: https://drive.google.com/file/d/1kb9nrzFjrr2IPcq4ATBQQOUw6vaTpFJ7/view?usp=drive_link | F13: =IFERROR(__xludf.DUMMYFUNCTION("IF(E13="""", """", ""https://drive.google.com/uc?export=view&id="" & REGEXEXTRACT(E13, ""/d/(.*)/""))"),"https://drive.google.com/uc?export=view&id=1kb9nrzFjrr2IPcq4ATBQQOUw6vaTpFJ7") -> https://drive.google.com/uc?export=view&id=1kb9nrzFjrr2IPcq4ATBQQOUw6vaTpFJ7
A14: No.013 | B14: 花朵纏繞的墓地 | C14: 原野之花 ×4、墓碑 ×1 | D14: 卡拉卡拉、嘎啦嘎啦 | E14: https://drive.google.com/file/d/14MtBLuKH364jLo-v3egXmfdVfeh5Nhz9/view?usp=drive_link | F14: =IFERROR(__xludf.DUMMYFUNCTION("IF(E14="""", """", ""https://drive.google.com/uc?export=view&id="" & REGEXEXTRACT(E14, ""/d/(.*)/""))"),"https://drive.google.com/uc?export=view&id=14MtBLuKH364jLo-v3egXmfdVfeh5Nhz9") -> https://drive.google.com/uc?export=view&id=14MtBLuKH364jLo-v3egXmfdVfeh5Nhz9
A15: No.014 | B15: 花園 | C15: 樹籬(任意) ×4、原野之花 ×4 | D15: 派拉斯、派拉斯特 | E15: https://drive.google.com/file/d/14nbZVUvlsjY-LDtwN3AQa2hzZWDlnvgf/view?usp=drive_link | F15: =IFERROR(__xludf.DUMMYFUNCTION("IF(E15="""", """", ""https://drive.google.com/uc?export=view&id="" & REGEXEXTRACT(E15, ""/d/(.*)/""))"),"https://drive.google.com/uc?export=view&id=14nbZVUvlsjY-LDtwN3AQa2hzZWDlnvgf") -> https://drive.google.com/uc?export=view&id=14nbZVUvlsjY-LDtwN3AQa2hzZWDlnvgf
A16: No.015 | B16: 新鮮蔬菜田 | C16: 蔬菜田(任意) ×8 | D16: 螺釘地鼠、龍頭地鼠、木木梟（空空鎮) | E16: https://drive.google.com/file/d/1nDD6CuoMnLoga-f0PpsRtqWD57UfRBkx/view?usp=drive_link | F16: =IFERROR(__xludf.DUMMYFUNCTION("IF(E16="""", """", ""https://drive.google.com/uc?export=view&id="" & REGEXEXTRACT(E16, ""/d/(.*)/""))"),"https://drive.google.com/uc?export=view&id=1nDD6CuoMnLoga-f0PpsRtqWD57UfRBkx") -> https://drive.google.com/uc?export=view&id=1nDD6CuoMnLoga-f0PpsRtqWD57UfRBkx
A17: No.016 | B17: 乘上暖風 | C17: 營火 ×3 | D17: 飄飄球 | E17: https://drive.google.com/file/d/1GWhrzo7rxLbs37rHVEullF_ENsxgNAHk/view?usp=drive_link | F17: =IFERROR(__xludf.DUMMYFUNCTION("IF(E17="""", """", ""https://drive.google.com/uc?export=view&id="" & REGEXEXTRACT(E17, ""/d/(.*)/""))"),"https://drive.google.com/uc?export=view&id=1GWhrzo7rxLbs37rHVEullF_ENsxgNAHk") -> https://drive.google.com/uc?export=view&id=1GWhrzo7rxLbs37rHVEullF_ENsxgNAHk
A18: No.017 | B18: 露營組合 | C18: 營火 ×1、乾草桌 ×1、乾草椅 ×1 | D18: 火恐龍 | E18: https://drive.google.com/file/d/1RhhU84KkyO7NlAJy7orPp0p9Gvcqfa7p/view?usp=drive_link | F18: =IFERROR(__xludf.DUMMYFUNCTION("IF(E18="""", """", ""https://drive.google.com/uc?export=view&id="" & REGEXEXTRACT(E18, ""/d/(.*)/""))"),"https://drive.google.com/uc?export=view&id=1RhhU84KkyO7NlAJy7orPp0p9Gvcqfa7p") -> https://drive.google.com/uc?export=view&id=1RhhU84KkyO7NlAJy7orPp0p9Gvcqfa7p
A19: No.018 | B19: 修行瀑布 | C19: 椅子(任意) ×1、水 ×2、瀑布 ×1 | D19: 無畏小子 | E19: https://drive.google.com/file/d/1xjXqd9TAn4SNoGBre-Gwh6YcMaT9nnTd/view?usp=drive_link | F19: =IFERROR(__xludf.DUMMYFUNCTION("IF(E19="""", """", ""https://drive.google.com/uc?export=view&id="" & REGEXEXTRACT(E19, ""/d/(.*)/""))"),"https://drive.google.com/uc?export=view&id=1xjXqd9TAn4SNoGBre-Gwh6YcMaT9nnTd") -> https://drive.google.com/uc?export=view&id=1xjXqd9TAn4SNoGBre-Gwh6YcMaT9nnTd
A20: No.019 | B20: 餓肚肚用餐區 | C20: 椅子(任意) ×1、桌子(任意) ×1、盤子上的食物 ×1 | D20: 溶食獸 | E20: https://drive.google.com/file/d/1NBZAjEUjlnSON7vZLet5XIsqsjVF3DG7/view?usp=drive_link | F20: =IFERROR(__xludf.DUMMYFUNCTION("IF(E20="""", """", ""https://drive.google.com/uc?export=view&id="" & REGEXEXTRACT(E20, ""/d/(.*)/""))"),"https://drive.google.com/uc?export=view&id=1NBZAjEUjlnSON7vZLet5XIsqsjVF3DG7") -> https://drive.google.com/uc?export=view&id=1NBZAjEUjlnSON7vZLet5XIsqsjVF3DG7
A21: No.020 | B21: 野餐風餐桌 | C21: 椅子(任意) ×2、桌子(任意) ×1、籃子 ×1 | D21: 皮丘(乾巴巴荒野)、皮卡丘（空空鎮) | E21: https://drive.google.com/file/d/1xLZR7Tsp1ZMTqDTbGVVvpw5bqZ1CuvGY/view?usp=drive_link | F21: =IFERROR(__xludf.DUMMYFUNCTION("IF(E21="""", """", ""https://drive.google.com/uc?export=view&id="" & REGEXEXTRACT(E21, ""/d/(.*)/""))"),"https://drive.google.com/uc?export=view&id=1xLZR7Tsp1ZMTqDTbGVVvpw5bqZ1CuvGY") -> https://drive.google.com/uc?export=view&id=1xLZR7Tsp1ZMTqDTbGVVvpw5bqZ1CuvGY
A22: No.021 | B22: 華麗的桌子 | C22: 椅子(任意) ×1、桌子(任意) ×1 | D22: 口呆花、大食花 | E22: https://drive.google.com/file/d/1IG2TcQGWffGFN2F84WUiO2bM9zvaewoY/view?usp=drive_link | F22: =IFERROR(__xludf.DUMMYFUNCTION("IF(E22="""", """", ""https://drive.google.com/uc?export=view&id="" & REGEXEXTRACT(E22, ""/d/(.*)/""))"),"https://drive.google.com/uc?export=view&id=1IG2TcQGWffGFN2F84WUiO2bM9zvaewoY") -> https://drive.google.com/uc?export=view&id=1IG2TcQGWffGFN2F84WUiO2bM9zvaewoY
A23: No.022 | B23: 綠色的長椅 | C23: 樹籬(任意) ×2、椅子(長條) ×1 | D23: 妙蛙種子、妙蛙草、巨蔓藤(需連線去對方的島) | E23: https://drive.google.com/file/d/1yLkAA6Es4XvbY7OFs0wlQp1MtiuQ-Gqu/view?usp=drive_link | F23: =IFERROR(__xludf.DUMMYFUNCTION("IF(E23="""", """", ""https://drive.google.com/uc?export=view&id="" & REGEXEXTRACT(E23, ""/d/(.*)/""))"),"https://drive.google.com/uc?export=view&id=1yLkAA6Es4XvbY7OFs0wlQp1MtiuQ-Gqu") -> https://drive.google.com/uc?export=view&id=1yLkAA6Es4XvbY7OFs0wlQp1MtiuQ-Gqu
A24: No.023 | B24: 光照的長椅 | C24: 椅子(長條) ×1、路燈(任意) ×1 | D24: 毛球 | E24: https://drive.google.com/file/d/1vZH2kamMfuXWmuQ4KlWODZnxqtptXSOp/view?usp=drive_link | F24: =IFERROR(__xludf.DUMMYFUNCTION("IF(E24="""", """", ""https://drive.google.com/uc?export=view&id="" & REGEXEXTRACT(E24, ""/d/(.*)/""))"),"https://drive.google.com/uc?export=view&id=1vZH2kamMfuXWmuQ4KlWODZnxqtptXSOp") -> https://drive.google.com/uc?export=view&id=1vZH2kamMfuXWmuQ4KlWODZnxqtptXSOp
A25: No.024 | B25: 健身區用餐區 | C25: 沙包 ×1、椅子(任意) ×1 | D25: 快拳郎 | E25: https://drive.google.com/file/d/1Ym45okARDdkyfF_ZzR3BD0qawn-ye3gq/view?usp=drive_link | F25: =IFERROR(__xludf.DUMMYFUNCTION("IF(E25="""", """", ""https://drive.google.com/uc?export=view&id="" & REGEXEXTRACT(E25, ""/d/(.*)/""))"),"https://drive.google.com/uc?export=view&id=1Ym45okARDdkyfF_ZzR3BD0qawn-ye3gq") -> https://drive.google.com/uc?export=view&id=1Ym45okARDdkyfF_ZzR3BD0qawn-ye3gq
A26: No.025 | B26: 緊急救護站 | C26: 椅子(任意) ×1、桌子(任意) ×1、急救箱 ×1 | D26: 飛腿郎 | E26: https://drive.google.com/file/d/1yBISxXekCdWZcFW5CppnNvAgf0qMIJHx/view?usp=drive_link | F26: =IFERROR(__xludf.DUMMYFUNCTION("IF(E26="""", """", ""https://drive.google.com/uc?export=view&id="" & REGEXEXTRACT(E26, ""/d/(.*)/""))"),"https://drive.google.com/uc?export=view&id=1yBISxXekCdWZcFW5CppnNvAgf0qMIJHx") -> https://drive.google.com/uc?export=view&id=1yBISxXekCdWZcFW5CppnNvAgf0qMIJHx
A27: No.026 | B27: 健身區救護站 | C27: 桌子(任意) ×1、沙包 ×1、急救箱 ×1 | D27: 戰舞郎 | E27: https://drive.google.com/file/d/1h933OGLQfet6ZWMyP4kodMMC1eiYvZPz/view?usp=drive_link | F27: =IFERROR(__xludf.DUMMYFUNCTION("IF(E27="""", """", ""https://drive.google.com/uc?export=view&id="" & REGEXEXTRACT(E27, ""/d/(.*)/""))"),"https://drive.google.com/uc?export=view&id=1h933OGLQfet6ZWMyP4kodMMC1eiYvZPz") -> https://drive.google.com/uc?export=view&id=1h933OGLQfet6ZWMyP4kodMMC1eiYvZPz
A28: No.027 | B28: 指路牌 | C28: 箭頭告示牌 ×1、木頭小路 ×3 | D28: 無殼海兔 | E28: https://drive.google.com/file/d/1Z1TRDksTSds7c2xIaT6z4Dpe09rP2pbJ/view?usp=drive_link | F28: =IFERROR(__xludf.DUMMYFUNCTION("IF(E28="""", """", ""https://drive.google.com/uc?export=view&id="" & REGEXEXTRACT(E28, ""/d/(.*)/""))"),"https://drive.google.com/uc?export=view&id=1Z1TRDksTSds7c2xIaT6z4Dpe09rP2pbJ") -> https://drive.google.com/uc?export=view&id=1Z1TRDksTSds7c2xIaT6z4Dpe09rP2pbJ
A29: No.028 | B29: 載上大行李 | C29: 手推車 ×1、木箱 ×2 | D29: 鐵骨土人、小鍛匠（空空鎮)、巧鍛匠（空空鎮) | E29: https://drive.google.com/file/d/1dd2IMbyTsIgCoxi6TfTAo7Y6cTjh_omG/view?usp=drive_link | F29: =IFERROR(__xludf.DUMMYFUNCTION("IF(E29="""", """", ""https://drive.google.com/uc?export=view&id="" & REGEXEXTRACT(E29, ""/d/(.*)/""))"),"https://drive.google.com/uc?export=view&id=1dd2IMbyTsIgCoxi6TfTAo7Y6cTjh_omG") -> https://drive.google.com/uc?export=view&id=1dd2IMbyTsIgCoxi6TfTAo7Y6cTjh_omG
A30: No.029 | B30: 樵夫的工作區 | C30: 圓木椅 ×1、手推車 ×1、樹樁 ×1、圓木桌 ×1 | D30: 牙牙（★）、斧牙龍（★★）、雙斧戰龍（★★★） | E30: https://drive.google.com/file/d/1uj8O15kVRxPvY-VhrExpqYdkyvoPY3dS/view?usp=drive_link | F30: =IFERROR(__xludf.DUMMYFUNCTION("IF(E30="""", """", ""https://drive.google.com/uc?export=view&id="" & REGEXEXTRACT(E30, ""/d/(.*)/""))"),"https://drive.google.com/uc?export=view&id=1uj8O15kVRxPvY-VhrExpqYdkyvoPY3dS") -> https://drive.google.com/uc?export=view&id=1uj8O15kVRxPvY-VhrExpqYdkyvoPY3dS
A31: No.030 | B31: 布偶伴好眠 | C31: 床鋪(任意) ×1 | D31: 飄飄球、小卡比獸（空空鎮) | E31: https://drive.google.com/file/d/1yTMvl-TTPdZvYO8Dss-kfVa18l1S8hKp/view?usp=drive_link | F31: =IFERROR(__xludf.DUMMYFUNCTION("IF(E31="""", """", ""https://drive.google.com/uc?export=view&id="" & REGEXEXTRACT(E31, ""/d/(.*)/""))"),"https://drive.google.com/uc?export=view&id=1yTMvl-TTPdZvYO8Dss-kfVa18l1S8hKp") -> https://drive.google.com/uc?export=view&id=1yTMvl-TTPdZvYO8Dss-kfVa18l1S8hKp
A32: No.031 | B32: 柔光伴好眠 | C32: 床鋪(任意) ×1、桌子(任意) ×1、細長蠟燭 ×1 | D32: 咕咕、貓頭夜鷹 | E32: https://drive.google.com/file/d/1HDoKzr-bOVCO4MZBahsLi-5SukLEUApY/view?usp=drive_link | F32: =IFERROR(__xludf.DUMMYFUNCTION("IF(E32="""", """", ""https://drive.google.com/uc?export=view&id="" & REGEXEXTRACT(E32, ""/d/(.*)/""))"),"https://drive.google.com/uc?export=view&id=1HDoKzr-bOVCO4MZBahsLi-5SukLEUApY") -> https://drive.google.com/uc?export=view&id=1HDoKzr-bOVCO4MZBahsLi-5SukLEUApY
A33: No.032 | B33: 墓前的供品 | C33: 墓碑 ×1、細長蠟燭 ×2、盤子上的食物 ×1 | D33: 燭光靈 | E33: https://drive.google.com/file/d/1lYfXfavq0TBl9HHF8eqIUvjJFvldc6GB/view?usp=drive_link | F33: =IFERROR(__xludf.DUMMYFUNCTION("IF(E33="""", """", ""https://drive.google.com/uc?export=view&id="" & REGEXEXTRACT(E33, ""/d/(.*)/""))"),"https://drive.google.com/uc?export=view&id=1lYfXfavq0TBl9HHF8eqIUvjJFvldc6GB") -> https://drive.google.com/uc?export=view&id=1lYfXfavq0TBl9HHF8eqIUvjJFvldc6GB
A34: No.033 | B34: 詭異墓前的供品 | C34: 可疑的蠟燭 ×2、墓碑 ×1、盤子上的食物 ×1 | D34: 燭光靈、燈火幽靈、水晶燈火靈 | E34: https://drive.google.com/file/d/1NyGxjwiINsObEZv5eZydpDHkY7Noicfg/view?usp=drive_link | F34: =IFERROR(__xludf.DUMMYFUNCTION("IF(E34="""", """", ""https://drive.google.com/uc?export=view&id="" & REGEXEXTRACT(E34, ""/d/(.*)/""))"),"https://drive.google.com/uc?export=view&id=1NyGxjwiINsObEZv5eZydpDHkY7Noicfg") -> https://drive.google.com/uc?export=view&id=1NyGxjwiINsObEZv5eZydpDHkY7Noicfg
A35: No.034 | B35: 吉利蛋休息處 | C35: 樹籬(任意) ×6、椅子(長條) ×1 | D35: 霸王花、美麗花 | E35: https://drive.google.com/file/d/1cKJ8IPz3WQ6DG1vQb1N7wvPVKF5UWM2J/view?usp=drive_link | F35: =IFERROR(__xludf.DUMMYFUNCTION("IF(E35="""", """", ""https://drive.google.com/uc?export=view&id="" & REGEXEXTRACT(E35, ""/d/(.*)/""))"),"https://drive.google.com/uc?export=view&id=1cKJ8IPz3WQ6DG1vQb1N7wvPVKF5UWM2J") -> https://drive.google.com/uc?export=view&id=1cKJ8IPz3WQ6DG1vQb1N7wvPVKF5UWM2J
A36: No.035 | B36: 光與香氣的勾引 | C36: 盤子上的食物 ×1 | D36: 口呆花 | E36: https://drive.google.com/file/d/1joFxiLq6Xqr-ZXZ8-7vBKfpK-Yxb8iHd/view?usp=drive_link | F36: =IFERROR(__xludf.DUMMYFUNCTION("IF(E36="""", """", ""https://drive.google.com/uc?export=view&id="" & REGEXEXTRACT(E36, ""/d/(.*)/""))"),"https://drive.google.com/uc?export=view&id=1joFxiLq6Xqr-ZXZ8-7vBKfpK-Yxb8iHd") -> https://drive.google.com/uc?export=view&id=1joFxiLq6Xqr-ZXZ8-7vBKfpK-Yxb8iHd
A37: No.036 | B37: 在陰涼處漂浮玩水 | C37: 海灘傘 ×1、水 ×2 | D37: 水箭龜 | E37: https://drive.google.com/file/d/1Viy3kDTiRGBHZphYMHRmYmkKuJx5NMWw/view?usp=drive_link | F37: =IFERROR(__xludf.DUMMYFUNCTION("IF(E37="""", """", ""https://drive.google.com/uc?export=view&id="" & REGEXEXTRACT(E37, ""/d/(.*)/""))"),"https://drive.google.com/uc?export=view&id=1Viy3kDTiRGBHZphYMHRmYmkKuJx5NMWw") -> https://drive.google.com/uc?export=view&id=1Viy3kDTiRGBHZphYMHRmYmkKuJx5NMWw
A38: No.037 | B38: 乾爽草叢 | C38: 枯萎的綠草 ×4、沙沙岩石 ×1 | D38: 大岩蛇 | E38: https://drive.google.com/file/d/1LytccQl21AjbkiqUQqPcbN_TZYKmN7dr/view?usp=drive_link | F38: =IFERROR(__xludf.DUMMYFUNCTION("IF(E38="""", """", ""https://drive.google.com/uc?export=view&id="" & REGEXEXTRACT(E38, ""/d/(.*)/""))"),"https://drive.google.com/uc?export=view&id=1LytccQl21AjbkiqUQqPcbN_TZYKmN7dr") -> https://drive.google.com/uc?export=view&id=1LytccQl21AjbkiqUQqPcbN_TZYKmN7dr
A39: No.038 | B39: 工廠倉庫 | C39: 路燈(任意) ×1 | D39: 小磁怪 | E39: https://drive.google.com/file/d/1sF8CRK36ZPLKDN3LDYnVNlnuoeIr2Yd5/view?usp=drive_link | F39: =IFERROR(__xludf.DUMMYFUNCTION("IF(E39="""", """", ""https://drive.google.com/uc?export=view&id="" & REGEXEXTRACT(E39, ""/d/(.*)/""))"),"https://drive.google.com/uc?export=view&id=1sF8CRK36ZPLKDN3LDYnVNlnuoeIr2Yd5") -> https://drive.google.com/uc?export=view&id=1sF8CRK36ZPLKDN3LDYnVNlnuoeIr2Yd5
A40: No.039 | B40: 豪華小雞飼料 | C40: 裝有樹果的籃子 ×1、木製鳥巢箱 ×1 | D40: 大比鳥（★） | E40: https://drive.google.com/file/d/1FD045dZ0IoiEuAzHpWD93NriuGWrxeyr/view?usp=drive_link | F40: =IFERROR(__xludf.DUMMYFUNCTION("IF(E40="""", """", ""https://drive.google.com/uc?export=view&id="" & REGEXEXTRACT(E40, ""/d/(.*)/""))"),"https://drive.google.com/uc?export=view&id=1FD045dZ0IoiEuAzHpWD93NriuGWrxeyr") -> https://drive.google.com/uc?export=view&id=1FD045dZ0IoiEuAzHpWD93NriuGWrxeyr
...

Sheet 寶可夢喜好表
A1: 編號 | B1: 寶可夢名稱 | C1: 專長 | D1: 掉落物 | E1: 喜歡的環境 | F1: 喜歡的事物 (標籤) | G1: 喜歡的口味 (範例) | H1: 棲息地1 / 道具) | I1: I 欄 (場景1 出現名單) | J1: 棲息地2 / 道具) | K1: K 欄 (場景2 出現名單) | L1: 棲息地3 / 道具) | M1: M 欄 (場景3 出現名單) | N1: 第 1 欄 | O1: 第 2 欄 | P1: 第 3 欄 | Q1: 第 4 欄 | R1: 第 5 欄 | S1: 第 6 欄 | T1: 第 7 欄 | U1: 第 8 欄 | V1: 第 9 欄 | W1: 第 10 欄 | X1: 第 11 欄 | Y1: 第 12 欄 | Z1: 第 13 欄
A2: 001 | B2: 妙蛙種子 | C2: 栽培 | E2: 明亮 | F2: 感受自然、柔軟、可愛、感受水、大家一起用 | G2: 甜 (桃桃果) | H2: =IFERROR(__xludf.DUMMYFUNCTION("IFERROR(INDEX(FILTER('棲息地'!$B$2:$B995 & "" / "" & '棲息地'!$C$2:$C995, ISNUMBER(SEARCH($B2, '棲息地'!$D$2:$D995))), 1), """")"),"綠色的草叢 / 綠草 ×4") -> 綠色的草叢 / 綠草 ×4 | I2: =IFERROR(__xludf.DUMMYFUNCTION("IFERROR(INDEX(FILTER('棲息地'!$D$2:$D995, ISNUMBER(SEARCH($B2, '棲息地'!$D$2:$D995))), 1), """")"),"妙蛙種子、小火龍、噴火龍、傑尼龜、走路草、小拳石（空空鎮)") -> 妙蛙種子、小火龍、噴火龍、傑尼龜、走路草、小拳石（空空鎮) | J2: =IFERROR(__xludf.DUMMYFUNCTION("IFERROR(INDEX(FILTER('棲息地'!$B$2:$B995 & "" / "" & '棲息地'!$C$2:$C995, ISNUMBER(SEARCH($B2, '棲息地'!$D$2:$D995))), 2), """")"),"綠色的長椅 / 樹籬(任意) ×2、椅子(長條) ×1") -> 綠色的長椅 / 樹籬(任意) ×2、椅子(長條) ×1 | K2: =IFERROR(__xludf.DUMMYFUNCTION("IFERROR(INDEX(FILTER('棲息地'!$D$2:$D995, ISNUMBER(SEARCH($B2, '棲息地'!$D$2:$D995))), 2), """")"),"妙蛙種子、妙蛙草、巨蔓藤(需連線去對方的島)") -> 妙蛙種子、妙蛙草、巨蔓藤(需連線去對方的島) | L2: =IFERROR(__xludf.DUMMYFUNCTION("IFERROR(INDEX(FILTER('棲息地'!$D$2:$D995, ISNUMBER(SEARCH($B2, '棲息地'!$D$2:$D995))), 3), """")"),"")
A3: 002 | B3: 妙蛙草 | C3: 栽培 | E3: 明亮 | F3: 感受自然、柔軟、可愛、花朵盛開、五彩繽紛 | G3: 酸 (番茄) | H3: =IFERROR(__xludf.DUMMYFUNCTION("IFERROR(INDEX(FILTER('棲息地'!$B$2:$B995 & "" / "" & '棲息地'!$C$2:$C995, ISNUMBER(SEARCH($B3, '棲息地'!$D$2:$D995))), 1), """")"),"整片的花海 / 原野之花 ×8") -> 整片的花海 / 原野之花 ×8 | I3: =IFERROR(__xludf.DUMMYFUNCTION("IFERROR(INDEX(FILTER('棲息地'!$D$2:$D995, ISNUMBER(SEARCH($B3, '棲息地'!$D$2:$D995))), 1), """")"),"妙蛙草、妙蛙花、蜂女王") -> 妙蛙草、妙蛙花、蜂女王 | J3: =IFERROR(__xludf.DUMMYFUNCTION("IFERROR(INDEX(FILTER('棲息地'!$B$2:$B995 & "" / "" & '棲息地'!$C$2:$C995, ISNUMBER(SEARCH($B3, '棲息地'!$D$2:$D995))), 2), """")"),"綠色的長椅 / 樹籬(任意) ×2、椅子(長條) ×1") -> 綠色的長椅 / 樹籬(任意) ×2、椅子(長條) ×1 | K3: =IFERROR(__xludf.DUMMYFUNCTION("IFERROR(INDEX(FILTER('棲息地'!$D$2:$D995, ISNUMBER(SEARCH($B3, '棲息地'!$D$2:$D995))), 2), """")"),"妙蛙種子、妙蛙草、巨蔓藤(需連線去對方的島)") -> 妙蛙種子、妙蛙草、巨蔓藤(需連線去對方的島) | L3: =IFERROR(__xludf.DUMMYFUNCTION("IFERROR(INDEX(FILTER('棲息地'!$D$2:$D995, ISNUMBER(SEARCH($B3, '棲息地'!$D$2:$D995))), 3), """")"),"")
A4: 003 | B4: 妙蛙花 | C4: 栽培、亂撒 | D4: 葉子 | E4: 明亮 | F4: 感受自然、柔軟、可愛、花朵盛開、華麗 | G4: 酸 (番茄) | H4: =IFERROR(__xludf.DUMMYFUNCTION("IFERROR(INDEX(FILTER('棲息地'!$B$2:$B995 & "" / "" & '棲息地'!$C$2:$C995, ISNUMBER(SEARCH($B4, '棲息地'!$D$2:$D995))), 1), """")"),"整片的花海 / 原野之花 ×8") -> 整片的花海 / 原野之花 ×8 | I4: =IFERROR(__xludf.DUMMYFUNCTION("IFERROR(INDEX(FILTER('棲息地'!$D$2:$D995, ISNUMBER(SEARCH($B4, '棲息地'!$D$2:$D995))), 1), """")"),"妙蛙草、妙蛙花、蜂女王") -> 妙蛙草、妙蛙花、蜂女王 | J4: =IFERROR(__xludf.DUMMYFUNCTION("IFERROR(INDEX(FILTER('棲息地'!$B$2:$B995 & "" / "" & '棲息地'!$C$2:$C995, ISNUMBER(SEARCH($B4, '棲息地'!$D$2:$D995))), 2), """")"),"庭園陽台 / 原野之花 ×4、花園燈 ×1、花園椅 ×1") -> 庭園陽台 / 原野之花 ×4、花園燈 ×1、花園椅 ×1 | K4: =IFERROR(__xludf.DUMMYFUNCTION("IFERROR(INDEX(FILTER('棲息地'!$D$2:$D995, ISNUMBER(SEARCH($B4, '棲息地'!$D$2:$D995))), 2), """")"),"妙蛙花") -> 妙蛙花 | L4: =IFERROR(__xludf.DUMMYFUNCTION("IFERROR(INDEX(FILTER('棲息地'!$D$2:$D995, ISNUMBER(SEARCH($B4, '棲息地'!$D$2:$D995))), 3), """")"),"")
A5: 004 | B5: 小火龍 | C5: 點火 | E5: 溫暖 | F5: 感受火焰、木製、堅硬、訓練、大家一起用 | G5: 辣 (紅蘿蔔) | H5: =IFERROR(__xludf.DUMMYFUNCTION("IFERROR(INDEX(FILTER('棲息地'!$B$2:$B995 & "" / "" & '棲息地'!$C$2:$C995, ISNUMBER(SEARCH($B5, '棲息地'!$D$2:$D995))), 1), """")"),"綠色的草叢 / 綠草 ×4") -> 綠色的草叢 / 綠草 ×4 | I5: =IFERROR(__xludf.DUMMYFUNCTION("IFERROR(INDEX(FILTER('棲息地'!$D$2:$D995, ISNUMBER(SEARCH($B5, '棲息地'!$D$2:$D995))), 1), """")"),"妙蛙種子、小火龍、噴火龍、傑尼龜、走路草、小拳石（空空鎮)") -> 妙蛙種子、小火龍、噴火龍、傑尼龜、走路草、小拳石（空空鎮) | J5: =IFERROR(__xludf.DUMMYFUNCTION("IFERROR(INDEX(FILTER('棲息地'!$B$2:$B995 & "" / "" & '棲息地'!$C$2:$C995, ISNUMBER(SEARCH($B5, '棲息地'!$D$2:$D995))), 2), """")"),"") | K5: =IFERROR(__xludf.DUMMYFUNCTION("IFERROR(INDEX(FILTER('棲息地'!$D$2:$D995, ISNUMBER(SEARCH($B5, '棲息地'!$D$2:$D995))), 2), """")"),"") | L5: =IFERROR(__xludf.DUMMYFUNCTION("IFERROR(INDEX(FILTER('棲息地'!$D$2:$D995, ISNUMBER(SEARCH($B5, '棲息地'!$D$2:$D995))), 3), """")"),"")
A6: 005 | B6: 火恐龍 | C6: 點火 | E6: 溫暖 | F6: 感受火焰、木製、堅硬、訓練、交通工具 | G6: 辣 (紅蘿蔔) | H6: =IFERROR(__xludf.DUMMYFUNCTION("IFERROR(INDEX(FILTER('棲息地'!$B$2:$B995 & "" / "" & '棲息地'!$C$2:$C995, ISNUMBER(SEARCH($B6, '棲息地'!$D$2:$D995))), 1), """")"),"露營組合 / 營火 ×1、乾草桌 ×1、乾草椅 ×1") -> 露營組合 / 營火 ×1、乾草桌 ×1、乾草椅 ×1 | I6: =IFERROR(__xludf.DUMMYFUNCTION("IFERROR(INDEX(FILTER('棲息地'!$D$2:$D995, ISNUMBER(SEARCH($B6, '棲息地'!$D$2:$D995))), 1), """")"),"火恐龍") -> 火恐龍 | J6: =IFERROR(__xludf.DUMMYFUNCTION("IFERROR(INDEX(FILTER('棲息地'!$B$2:$B995 & "" / "" & '棲息地'!$C$2:$C995, ISNUMBER(SEARCH($B6, '棲息地'!$D$2:$D995))), 2), """")"),"") | K6: =IFERROR(__xludf.DUMMYFUNCTION("IFERROR(INDEX(FILTER('棲息地'!$D$2:$D995, ISNUMBER(SEARCH($B6, '棲息地'!$D$2:$D995))), 2), """")"),"") | L6: =IFERROR(__xludf.DUMMYFUNCTION("IFERROR(INDEX(FILTER('棲息地'!$D$2:$D995, ISNUMBER(SEARCH($B6, '棲息地'!$D$2:$D995))), 3), """")"),"")
A7: 006 | B7: 噴火龍 | C7: 點火、飛翔 | E7: 溫暖 | F7: 感受火焰、感受風、木製、訓練、華麗 | G7: 辣 (紅蘿蔔) | H7: =IFERROR(__xludf.DUMMYFUNCTION("IFERROR(INDEX(FILTER('棲息地'!$B$2:$B995 & "" / "" & '棲息地'!$C$2:$C995, ISNUMBER(SEARCH($B7, '棲息地'!$D$2:$D995))), 1), """")"),"綠色的草叢 / 綠草 ×4") -> 綠色的草叢 / 綠草 ×4 | I7: =IFERROR(__xludf.DUMMYFUNCTION("IFERROR(INDEX(FILTER('棲息地'!$D$2:$D995, ISNUMBER(SEARCH($B7, '棲息地'!$D$2:$D995))), 1), """")"),"妙蛙種子、小火龍、噴火龍、傑尼龜、走路草、小拳石（空空鎮)") -> 妙蛙種子、小火龍、噴火龍、傑尼龜、走路草、小拳石（空空鎮) | J7: =IFERROR(__xludf.DUMMYFUNCTION("IFERROR(INDEX(FILTER('棲息地'!$B$2:$B995 & "" / "" & '棲息地'!$C$2:$C995, ISNUMBER(SEARCH($B7, '棲息地'!$D$2:$D995))), 2), """")"),"樹果露營大餐 / 晴天漂浮泡泡娃娃 ×2、營火 ×1、樹果籃 ×1、高處 ×1") -> 樹果露營大餐 / 晴天漂浮泡泡娃娃 ×2、營火 ×1、樹果籃 ×1、高處 ×1 | K7: =IFERROR(__xludf.DUMMYFUNCTION("IFERROR(INDEX(FILTER('棲息地'!$D$2:$D995, ISNUMBER(SEARCH($B7, '棲息地'!$D$2:$D995))), 2), """")"),"噴火龍") -> 噴火龍 | L7: =IFERROR(__xludf.DUMMYFUNCTION("IFERROR(INDEX(FILTER('棲息地'!$D$2:$D995, ISNUMBER(SEARCH($B7, '棲息地'!$D$2:$D995))), 3), """")"),"")
A8: 007 | B8: 傑尼龜 | C8: 滋潤 | E8: 滋潤 | F8: 感受水、整潔、療癒傷口、可愛、大家一起用 | G8: 甜 (桃桃果) | H8: =IFERROR(__xludf.DUMMYFUNCTION("IFERROR(INDEX(FILTER('棲息地'!$B$2:$B995 & "" / "" & '棲息地'!$C$2:$C995, ISNUMBER(SEARCH($B8, '棲息地'!$D$2:$D995))), 1), """")"),"綠色的草叢 / 綠草 ×4") -> 綠色的草叢 / 綠草 ×4 | I8: =IFERROR(__xludf.DUMMYFUNCTION("IFERROR(INDEX(FILTER('棲息地'!$D$2:$D995, ISNUMBER(SEARCH($B8, '棲息地'!$D$2:$D995))), 1), """")"),"妙蛙種子、小火龍、噴火龍、傑尼龜、走路草、小拳石（空空鎮)") -> 妙蛙種子、小火龍、噴火龍、傑尼龜、走路草、小拳石（空空鎮) | J8: =IFERROR(__xludf.DUMMYFUNCTION("IFERROR(INDEX(FILTER('棲息地'!$B$2:$B995 & "" / "" & '棲息地'!$C$2:$C995, ISNUMBER(SEARCH($B8, '棲息地'!$D$2:$D995))), 2), """")"),"濕潤的草地 / 綠草 ×4、水 ×2") -> 濕潤的草地 / 綠草 ×4、水 ×2 | K8: =IFERROR(__xludf.DUMMYFUNCTION("IFERROR(INDEX(FILTER('棲息地'!$D$2:$D995, ISNUMBER(SEARCH($B8, '棲息地'!$D$2:$D995))), 2), """")"),"傑尼龜、卡咪龜、水箭龜、黏美兒、古月鳥（空空鎮)") -> 傑尼龜、卡咪龜、水箭龜、黏美兒、古月鳥（空空鎮) | L8: =IFERROR(__xludf.DUMMYFUNCTION("IFERROR(INDEX(FILTER('棲息地'!$D$2:$D995, ISNUMBER(SEARCH($B8, '棲息地'!$D$2:$D995))), 3), """")"),"")
A9: 008 | B9: 卡咪龜 | C9: 滋潤 | E9: 滋潤 | F9: 感受水、整潔、療癒傷口、訓練、堅硬 | G9: 辣 (紅蘿蔔) | H9: =IFERROR(__xludf.DUMMYFUNCTION("IFERROR(INDEX(FILTER('棲息地'!$B$2:$B995 & "" / "" & '棲息地'!$C$2:$C995, ISNUMBER(SEARCH($B9, '棲息地'!$D$2:$D995))), 1), """")"),"濕潤的草地 / 綠草 ×4、水 ×2") -> 濕潤的草地 / 綠草 ×4、水 ×2 | I9: =IFERROR(__xludf.DUMMYFUNCTION("IFERROR(INDEX(FILTER('棲息地'!$D$2:$D995, ISNUMBER(SEARCH($B9, '棲息地'!$D$2:$D995))), 1), """")"),"傑尼龜、卡咪龜、水箭龜、黏美兒、古月鳥（空空鎮)") -> 傑尼龜、卡咪龜、水箭龜、黏美兒、古月鳥（空空鎮) | J9: =IFERROR(__xludf.DUMMYFUNCTION("IFERROR(INDEX(FILTER('棲息地'!$B$2:$B995 & "" / "" & '棲息地'!$C$2:$C995, ISNUMBER(SEARCH($B9, '棲息地'!$D$2:$D995))), 2), """")"),"") | K9: =IFERROR(__xludf.DUMMYFUNCTION("IFERROR(INDEX(FILTER('棲息地'!$D$2:$D995, ISNUMBER(SEARCH($B9, '棲息地'!$D$2:$D995))), 2), """")"),"") | L9: =IFERROR(__xludf.DUMMYFUNCTION("IFERROR(INDEX(FILTER('棲息地'!$D$2:$D995, ISNUMBER(SEARCH($B9, '棲息地'!$D$2:$D995))), 3), """")"),"")
A10: 009 | B10: 水箭龜 | C10: 滋潤、交易 | E10: 滋潤 | F10: 感受水、整潔、療癒傷口、訓練、華麗 | G10: 酸 (番茄) | H10: =IFERROR(__xludf.DUMMYFUNCTION("IFERROR(INDEX(FILTER('棲息地'!$B$2:$B995 & "" / "" & '棲息地'!$C$2:$C995, ISNUMBER(SEARCH($B10, '棲息地'!$D$2:$D995))), 1), """")"),"濕潤的草地 / 綠草 ×4、水 ×2") -> 濕潤的草地 / 綠草 ×4、水 ×2 | I10: =IFERROR(__xludf.DUMMYFUNCTION("IFERROR(INDEX(FILTER('棲息地'!$D$2:$D995, ISNUMBER(SEARCH($B10, '棲息地'!$D$2:$D995))), 1), """")"),"傑尼龜、卡咪龜、水箭龜、黏美兒、古月鳥（空空鎮)") -> 傑尼龜、卡咪龜、水箭龜、黏美兒、古月鳥（空空鎮) | J10: =IFERROR(__xludf.DUMMYFUNCTION("IFERROR(INDEX(FILTER('棲息地'!$B$2:$B995 & "" / "" & '棲息地'!$C$2:$C995, ISNUMBER(SEARCH($B10, '棲息地'!$D$2:$D995))), 2), """")"),"在陰涼處漂浮玩水 / 海灘傘 ×1、水 ×2") -> 在陰涼處漂浮玩水 / 海灘傘 ×1、水 ×2 | K10: =IFERROR(__xludf.DUMMYFUNCTION("IFERROR(INDEX(FILTER('棲息地'!$D$2:$D995, ISNUMBER(SEARCH($B10, '棲息地'!$D$2:$D995))), 2), """")"),"水箭龜") -> 水箭龜 | L10: =IFERROR(__xludf.DUMMYFUNCTION("IFERROR(INDEX(FILTER('棲息地'!$D$2:$D995, ISNUMBER(SEARCH($B10, '棲息地'!$D$2:$D995))), 3), """")"),"")
A11: 010 | B11: 波波 | C11: 找東西、飛翔 | E11: 明亮 | F11: 柔軟、感受風、觀賞樂趣、感受自然、遊樂場 | G11: 酸 (番茄) | H11: =IFERROR(__xludf.DUMMYFUNCTION("IFERROR(INDEX(FILTER('棲息地'!$B$2:$B995 & "" / "" & '棲息地'!$C$2:$C995, ISNUMBER(SEARCH($B11, '棲息地'!$D$2:$D995))), 1), """")"),"高崗的草叢 / 綠草 ×4、高處 ×1") -> 高崗的草叢 / 綠草 ×4、高處 ×1 | I11: =IFERROR(__xludf.DUMMYFUNCTION("IFERROR(INDEX(FILTER('棲息地'!$D$2:$D995, ISNUMBER(SEARCH($B11, '棲息地'!$D$2:$D995))), 1), """")"),"咕咕、波波、比比鳥") -> 咕咕、波波、比比鳥 | J11: =IFERROR(__xludf.DUMMYFUNCTION("IFERROR(INDEX(FILTER('棲息地'!$B$2:$B995 & "" / "" & '棲息地'!$C$2:$C995, ISNUMBER(SEARCH($B11, '棲息地'!$D$2:$D995))), 2), """")"),"漂亮的花田 / 原野之花 ×4") -> 漂亮的花田 / 原野之花 ×4 | K11: =IFERROR(__xludf.DUMMYFUNCTION("IFERROR(INDEX(FILTER('棲息地'!$D$2:$D995, ISNUMBER(SEARCH($B11, '棲息地'!$D$2:$D995))), 2), """")"),"咕咕、三蜜蜂、伊布、波波（空空鎮)、鴨嘴寶寶（空空鎮)") -> 咕咕、三蜜蜂、伊布、波波（空空鎮)、鴨嘴寶寶（空空鎮) | L11: =IFERROR(__xludf.DUMMYFUNCTION("IFERROR(INDEX(FILTER('棲息地'!$D$2:$D995, ISNUMBER(SEARCH($B11, '棲息地'!$D$2:$D995))), 3), """")"),"")
A12: 011 | B12: 比比鳥 | C12: 找東西、飛翔 | E12: 明亮 | F12: 柔軟、感受風、觀賞樂趣、感受自然、像食物 | G12: 辣 (紅蘿蔔) | H12: =IFERROR(__xludf.DUMMYFUNCTION("IFERROR(INDEX(FILTER('棲息地'!$B$2:$B995 & "" / "" & '棲息地'!$C$2:$C995, ISNUMBER(SEARCH($B12, '棲息地'!$D$2:$D995))), 1), """")"),"高崗的草叢 / 綠草 ×4、高處 ×1") -> 高崗的草叢 / 綠草 ×4、高處 ×1 | I12: =IFERROR(__xludf.DUMMYFUNCTION("IFERROR(INDEX(FILTER('棲息地'!$D$2:$D995, ISNUMBER(SEARCH($B12, '棲息地'!$D$2:$D995))), 1), """")"),"咕咕、波波、比比鳥") -> 咕咕、波波、比比鳥 | J12: =IFERROR(__xludf.DUMMYFUNCTION("IFERROR(INDEX(FILTER('棲息地'!$B$2:$B995 & "" / "" & '棲息地'!$C$2:$C995, ISNUMBER(SEARCH($B12, '棲息地'!$D$2:$D995))), 2), """")"),"") | K12: =IFERROR(__xludf.DUMMYFUNCTION("IFERROR(INDEX(FILTER('棲息地'!$D$2:$D995, ISNUMBER(SEARCH($B12, '棲息地'!$D$2:$D995))), 2), """")"),"") | L12: =IFERROR(__xludf.DUMMYFUNCTION("IFERROR(INDEX(FILTER('棲息地'!$D$2:$D995, ISNUMBER(SEARCH($B12, '棲息地'!$D$2:$D995))), 3), """")"),"")
A13: 012 | B13: 大比鳥 | C13: 伐木、飛翔 | E13: 明亮 | F13: 柔軟、感受風、木製、感受自然、華麗 | G13: 酸 (番茄) | H13: =IFERROR(__xludf.DUMMYFUNCTION("IFERROR(INDEX(FILTER('棲息地'!$B$2:$B995 & "" / "" & '棲息地'!$C$2:$C995, ISNUMBER(SEARCH($B13, '棲息地'!$D$2:$D995))), 1), """")"),"豪華小雞飼料 / 裝有樹果的籃子 ×1、木製鳥巢箱 ×1") -> 豪華小雞飼料 / 裝有樹果的籃子 ×1、木製鳥巢箱 ×1 | I13: =IFERROR(__xludf.DUMMYFUNCTION("IFERROR(INDEX(FILTER('棲息地'!$D$2:$D995, ISNUMBER(SEARCH($B13, '棲息地'!$D$2:$D995))), 1), """")"),"大比鳥（★）") -> 大比鳥（★） | J13: =IFERROR(__xludf.DUMMYFUNCTION("IFERROR(INDEX(FILTER('棲息地'!$B$2:$B995 & "" / "" & '棲息地'!$C$2:$C995, ISNUMBER(SEARCH($B13, '棲息地'!$D$2:$D995))), 2), """")"),"") | K13: =IFERROR(__xludf.DUMMYFUNCTION("IFERROR(INDEX(FILTER('棲息地'!$D$2:$D995, ISNUMBER(SEARCH($B13, '棲息地'!$D$2:$D995))), 2), """")"),"") | L13: =IFERROR(__xludf.DUMMYFUNCTION("IFERROR(INDEX(FILTER('棲息地'!$D$2:$D995, ISNUMBER(SEARCH($B13, '棲息地'!$D$2:$D995))), 3), """")"),"")
A14: 013 | B14: 走路草 | C14: 栽培 | E14: 滋潤 | F14: 感受自然、感受土、柔軟、花朵盛開、感受水 | G14: 苦 (馬鈴薯) | H14: =IFERROR(__xludf.DUMMYFUNCTION("IFERROR(INDEX(FILTER('棲息地'!$B$2:$B995 & "" / "" & '棲息地'!$C$2:$C995, ISNUMBER(SEARCH($B14, '棲息地'!$D$2:$D995))), 1), """")"),"綠色的草叢 / 綠草 ×4") -> 綠色的草叢 / 綠草 ×4 | I14: =IFERROR(__xludf.DUMMYFUNCTION("IFERROR(INDEX(FILTER('棲息地'!$D$2:$D995, ISNUMBER(SEARCH($B14, '棲息地'!$D$2:$D995))), 1), """")"),"妙蛙種子、小火龍、噴火龍、傑尼龜、走路草、小拳石（空空鎮)") -> 妙蛙種子、小火龍、噴火龍、傑尼龜、走路草、小拳石（空空鎮) | J14: =IFERROR(__xludf.DUMMYFUNCTION("IFERROR(INDEX(FILTER('棲息地'!$B$2:$B995 & "" / "" & '棲息地'!$C$2:$C995, ISNUMBER(SEARCH($B14, '棲息地'!$D$2:$D995))), 2), """")"),"") | K14: =IFERROR(__xludf.DUMMYFUNCTION("IFERROR(INDEX(FILTER('棲息地'!$D$2:$D995, ISNUMBER(SEARCH($B14, '棲息地'!$D$2:$D995))), 2), """")"),"") | L14: =IFERROR(__xludf.DUMMYFUNCTION("IFERROR(INDEX(FILTER('棲息地'!$D$2:$D995, ISNUMBER(SEARCH($B14, '棲息地'!$D$2:$D995))), 3), """")"),"")
A15: 014 | B15: 臭臭花 | C15: 栽培 | E15: 滋潤 | F15: 感受自然、感受土、柔軟、花朵盛開、垃圾 | G15: 澀 (小麥) | H15: =IFERROR(__xludf.DUMMYFUNCTION("IFERROR(INDEX(FILTER('棲息地'!$B$2:$B995 & "" / "" & '棲息地'!$C$2:$C995, ISNUMBER(SEARCH($B15, '棲息地'!$D$2:$D995))), 1), """")"),"南國氣氛 / 大椰子樹 ×1、海邊之花 ×4") -> 南國氣氛 / 大椰子樹 ×1、海邊之花 ×4 | I15: =IFERROR(__xludf.DUMMYFUNCTION("IFERROR(INDEX(FILTER('棲息地'!$D$2:$D995, ISNUMBER(SEARCH($B15, '棲息地'!$D$2:$D995))), 1), """")"),"椰蛋樹、臭臭花、蛋蛋") -> 椰蛋樹、臭臭花、蛋蛋 | J15: =IFERROR(__xludf.DUMMYFUNCTION("IFERROR(INDEX(FILTER('棲息地'!$B$2:$B995 & "" / "" & '棲息地'!$C$2:$C995, ISNUMBER(SEARCH($B15, '棲息地'!$D$2:$D995))), 2), """")"),"") | K15: =IFERROR(__xludf.DUMMYFUNCTION("IFERROR(INDEX(FILTER('棲息地'!$D$2:$D995, ISNUMBER(SEARCH($B15, '棲息地'!$D$2:$D995))), 2), """")"),"") | L15: =IFERROR(__xludf.DUMMYFUNCTION("IFERROR(INDEX(FILTER('棲息地'!$D$2:$D995, ISNUMBER(SEARCH($B15, '棲息地'!$D$2:$D995))), 3), """")"),"")
A16: 015 | B16: 霸王花 | C16: 栽培、亂撒 | D16: 葉子 | E16: 滋潤 | F16: 感受自然、感受土、柔軟、花朵盛開、五彩繽紛 | G16: 苦 (馬鈴薯) | H16: =IFERROR(__xludf.DUMMYFUNCTION("IFERROR(INDEX(FILTER('棲息地'!$B$2:$B995 & "" / "" & '棲息地'!$C$2:$C995, ISNUMBER(SEARCH($B16, '棲息地'!$D$2:$D995))), 1), """")"),"吉利蛋休息處 / 樹籬(任意) ×6、椅子(長條) ×1") -> 吉利蛋休息處 / 樹籬(任意) ×6、椅子(長條) ×1 | I16: =IFERROR(__xludf.DUMMYFUNCTION("IFERROR(INDEX(FILTER('棲息地'!$D$2:$D995, ISNUMBER(SEARCH($B16, '棲息地'!$D$2:$D995))), 1), """")"),"霸王花、美麗花") -> 霸王花、美麗花 | J16: =IFERROR(__xludf.DUMMYFUNCTION("IFERROR(INDEX(FILTER('棲息地'!$B$2:$B995 & "" / "" & '棲息地'!$C$2:$C995, ISNUMBER(SEARCH($B16, '棲息地'!$D$2:$D995))), 2), """")"),"") | K16: =IFERROR(__xludf.DUMMYFUNCTION("IFERROR(INDEX(FILTER('棲息地'!$D$2:$D995, ISNUMBER(SEARCH($B16, '棲息地'!$D$2:$D995))), 2), """")"),"") | L16: =IFERROR(__xludf.DUMMYFUNCTION("IFERROR(INDEX(FILTER('棲息地'!$D$2:$D995, ISNUMBER(SEARCH($B16, '棲息地'!$D$2:$D995))), 3), """")"),"")
A17: 016 | B17: 美麗花 | C17: 栽培、帶動氣氛 | E17: 明亮 | F17: 感受自然、花朵盛開、遊樂場、可愛、聲音 | G17: 酸 (番茄) | H17: =IFERROR(__xludf.DUMMYFUNCTION("IFERROR(INDEX(FILTER('棲息地'!$B$2:$B995 & "" / "" & '棲息地'!$C$2:$C995, ISNUMBER(SEARCH($B17, '棲息地'!$D$2:$D995))), 1), """")"),"吉利蛋休息處 / 樹籬(任意) ×6、椅子(長條) ×1") -> 吉利蛋休息處 / 樹籬(任意) ×6、椅子(長條) ×1 | I17: =IFERROR(__xludf.DUMMYFUNCTION("IFERROR(INDEX(FILTER('棲息地'!$D$2:$D995, ISNUMBER(SEARCH($B17, '棲息地'!$D$2:$D995))), 1), """")"),"霸王花、美麗花") -> 霸王花、美麗花 | J17: =IFERROR(__xludf.DUMMYFUNCTION("IFERROR(INDEX(FILTER('棲息地'!$B$2:$B995 & "" / "" & '棲息地'!$C$2:$C995, ISNUMBER(SEARCH($B17, '棲息地'!$D$2:$D995))), 2), """")"),"") | K17: =IFERROR(__xludf.DUMMYFUNCTION("IFERROR(INDEX(FILTER('棲息地'!$D$2:$D995, ISNUMBER(SEARCH($B17, '棲息地'!$D$2:$D995))), 2), """")"),"") | L17: =IFERROR(__xludf.DUMMYFUNCTION("IFERROR(INDEX(FILTER('棲息地'!$D$2:$D995, ISNUMBER(SEARCH($B17, '棲息地'!$D$2:$D995))), 3), """")"),"")
A18: 017 | B18: 派拉斯 | C18: 找東西 | E18: 滋潤 | F18: 感受自然、木製、觀賞樂趣、感受土、像食物 | G18: 苦 (馬鈴薯) | H18: =IFERROR(__xludf.DUMMYFUNCTION("IFERROR(INDEX(FILTER('棲息地'!$B$2:$B995 & "" / "" & '棲息地'!$C$2:$C995, ISNUMBER(SEARCH($B18, '棲息地'!$D$2:$D995))), 1), """")"),"高崗的花海 / 原野之花 ×4、高處 ×1") -> 高崗的花海 / 原野之花 ×4、高處 ×1 | I18: =IFERROR(__xludf.DUMMYFUNCTION("IFERROR(INDEX(FILTER('棲息地'!$D$2:$D995, ISNUMBER(SEARCH($B18, '棲息地'!$D$2:$D995))), 1), """")"),"派拉斯、派拉斯特") -> 派拉斯、派拉斯特 | J18: =IFERROR(__xludf.DUMMYFUNCTION("IFERROR(INDEX(FILTER('棲息地'!$B$2:$B995 & "" / "" & '棲息地'!$C$2:$C995, ISNUMBER(SEARCH($B18, '棲息地'!$D$2:$D995))), 2), """")"),"花園 / 樹籬(任意) ×4、原野之花 ×4") -> 花園 / 樹籬(任意) ×4、原野之花 ×4 | K18: =IFERROR(__xludf.DUMMYFUNCTION("IFERROR(INDEX(FILTER('棲息地'!$D$2:$D995, ISNUMBER(SEARCH($B18, '棲息地'!$D$2:$D995))), 2), """")"),"派拉斯、派拉斯特") -> 派拉斯、派拉斯特 | L18: =IFERROR(__xludf.DUMMYFUNCTION("IFERROR(INDEX(FILTER('棲息地'!$D$2:$D995, ISNUMBER(SEARCH($B18, '棲息地'!$D$2:$D995))), 3), """")"),"")
A19: 018 | B19: 派拉斯特 | C19: 找東西 | E19: 滋潤 | F19: 感受自然、木製、觀賞樂趣、感受土、不可思議 | G19: 苦 (馬鈴薯) | H19: =IFERROR(__xludf.DUMMYFUNCTION("IFERROR(INDEX(FILTER('棲息地'!$B$2:$B995 & "" / "" & '棲息地'!$C$2:$C995, ISNUMBER(SEARCH($B19, '棲息地'!$D$2:$D995))), 1), """")"),"高崗的花海 / 原野之花 ×4、高處 ×1") -> 高崗的花海 / 原野之花 ×4、高處 ×1 | I19: =IFERROR(__xludf.DUMMYFUNCTION("IFERROR(INDEX(FILTER('棲息地'!$D$2:$D995, ISNUMBER(SEARCH($B19, '棲息地'!$D$2:$D995))), 1), """")"),"派拉斯、派拉斯特") -> 派拉斯、派拉斯特 | J19: =IFERROR(__xludf.DUMMYFUNCTION("IFERROR(INDEX(FILTER('棲息地'!$B$2:$B995 & "" / "" & '棲息地'!$C$2:$C995, ISNUMBER(SEARCH($B19, '棲息地'!$D$2:$D995))), 2), """")"),"花園 / 樹籬(任意) ×4、原野之花 ×4") -> 花園 / 樹籬(任意) ×4、原野之花 ×4 | K19: =IFERROR(__xludf.DUMMYFUNCTION("IFERROR(INDEX(FILTER('棲息地'!$D$2:$D995, ISNUMBER(SEARCH($B19, '棲息地'!$D$2:$D995))), 2), """")"),"派拉斯、派拉斯特") -> 派拉斯、派拉斯特 | L19: =IFERROR(__xludf.DUMMYFUNCTION("IFERROR(INDEX(FILTER('棲息地'!$D$2:$D995, ISNUMBER(SEARCH($B19, '棲息地'!$D$2:$D995))), 3), """")"),"")
A20: 019 | B20: 毛球 | C20: 找東西 | E20: 明亮 | F20: 感受自然、木製、觀賞樂趣、看起來很難、有文字 | G20: 苦 (馬鈴薯) | H20: =IFERROR(__xludf.DUMMYFUNCTION("IFERROR(INDEX(FILTER('棲息地'!$B$2:$B995 & "" / "" & '棲息地'!$C$2:$C995, ISNUMBER(SEARCH($B20, '棲息地'!$D$2:$D995))), 1), """")"),"光照的草叢 / 草叢(任意) ×4、照明(任意) ×1") -> 光照的草叢 / 草叢(任意) ×4、照明(任意) ×1 | I20: =IFERROR(__xludf.DUMMYFUNCTION("IFERROR(INDEX(FILTER('棲息地'!$D$2:$D995, ISNUMBER(SEARCH($B20, '棲息地'!$D$2:$D995))), 1), """")"),"毛球、摩魯蛾") -> 毛球、摩魯蛾 | J20: =IFERROR(__xludf.DUMMYFUNCTION("IFERROR(INDEX(FILTER('棲息地'!$B$2:$B995 & "" / "" & '棲息地'!$C$2:$C995, ISNUMBER(SEARCH($B20, '棲息地'!$D$2:$D995))), 2), """")"),"光照的長椅 / 椅子(長條) ×1、路燈(任意) ×1") -> 光照的長椅 / 椅子(長條) ×1、路燈(任意) ×1 | K20: =IFERROR(__xludf.DUMMYFUNCTION("IFERROR(INDEX(FILTER('棲息地'!$D$2:$D995, ISNUMBER(SEARCH($B20, '棲息地'!$D$2:$D995))), 2), """")"),"毛球") -> 毛球 | L20: =IFERROR(__xludf.DUMMYFUNCTION("IFERROR(INDEX(FILTER('棲息地'!$D$2:$D995, ISNUMBER(SEARCH($B20, '棲息地'!$D$2:$D995))), 3), """")"),"")
A21: 020 | B21: 摩魯蛾 | C21: 找東西 | E21: 明亮 | F21: 感受自然、木製、觀賞樂趣、感受風、花朵盛開 | G21: 苦 (馬鈴薯) | H21: =IFERROR(__xludf.DUMMYFUNCTION("IFERROR(INDEX(FILTER('棲息地'!$B$2:$B995 & "" / "" & '棲息地'!$C$2:$C995, ISNUMBER(SEARCH($B21, '棲息地'!$D$2:$D995))), 1), """")"),"光照的草叢 / 草叢(任意) ×4、照明(任意) ×1") -> 光照的草叢 / 草叢(任意) ×4、照明(任意) ×1 | I21: =IFERROR(__xludf.DUMMYFUNCTION("IFERROR(INDEX(FILTER('棲息地'!$D$2:$D995, ISNUMBER(SEARCH($B21, '棲息地'!$D$2:$D995))), 1), """")"),"毛球、摩魯蛾") -> 毛球、摩魯蛾 | J21: =IFERROR(__xludf.DUMMYFUNCTION("IFERROR(INDEX(FILTER('棲息地'!$B$2:$B995 & "" / "" & '棲息地'!$C$2:$C995, ISNUMBER(SEARCH($B21, '棲息地'!$D$2:$D995))), 2), """")"),"") | K21: =IFERROR(__xludf.DUMMYFUNCTION("IFERROR(INDEX(FILTER('棲息地'!$D$2:$D995, ISNUMBER(SEARCH($B21, '棲息地'!$D$2:$D995))), 2), """")"),"") | L21: =IFERROR(__xludf.DUMMYFUNCTION("IFERROR(INDEX(FILTER('棲息地'!$D$2:$D995, ISNUMBER(SEARCH($B21, '棲息地'!$D$2:$D995))), 3), """")"),"")
A22: 021 | B22: 喇叭芽 | C22: 栽培、亂撒 | D22: 藤蔓繩 | E22: 滋潤 | F22: 感受自然、木製、感受土、感受水、花朵盛開 | G22: 澀 (小麥) | H22: =IFERROR(__xludf.DUMMYFUNCTION("IFERROR(INDEX(FILTER('棲息地'!$B$2:$B995 & "" / "" & '棲息地'!$C$2:$C995, ISNUMBER(SEARCH($B22, '棲息地'!$D$2:$D995))), 1), """")"),"樹蔭的草叢 / 大樹 ×1、綠草 ×4") -> 樹蔭的草叢 / 大樹 ×1、綠草 ×4 | I22: =IFERROR(__xludf.DUMMYFUNCTION("IFERROR(INDEX(FILTER('棲息地'!$D$2:$D995, ISNUMBER(SEARCH($B22, '棲息地'!$D$2:$D995))), 1), """")"),"飛天螳螂、喇叭芽、巨鉗螳螂（空空鎮)、赫拉克羅斯、凱羅斯、貪心栗鼠（空空鎮)") -> 飛天螳螂、喇叭芽、巨鉗螳螂（空空鎮)、赫拉克羅斯、凱羅斯、貪心栗鼠（空空鎮) | J22: =IFERROR(__xludf.DUMMYFUNCTION("IFERROR(INDEX(FILTER('棲息地'!$B$2:$B995 & "" / "" & '棲息地'!$C$2:$C995, ISNUMBER(SEARCH($B22, '棲息地'!$D$2:$D995))), 2), """")"),"") | K22: =IFERROR(__xludf.DUMMYFUNCTION("IFERROR(INDEX(FILTER('棲息地'!$D$2:$D995, ISNUMBER(SEARCH($B22, '棲息地'!$D$2:$D995))), 2), """")"),"") | L22: =IFERROR(__xludf.DUMMYFUNCTION("IFERROR(INDEX(FILTER('棲息地'!$D$2:$D995, ISNUMBER(SEARCH($B22, '棲息地'!$D$2:$D995))), 3), """")"),"")
A23: 022 | B23: 口呆花 | C23: 栽培、亂撒 | D23: 藤蔓繩 | E23: 滋潤 | F23: 感受自然、木製、感受土、五彩繽紛、花朵盛開 | G23: 苦 (馬鈴薯) | H23: =IFERROR(__xludf.DUMMYFUNCTION("IFERROR(INDEX(FILTER('棲息地'!$B$2:$B995 & "" / "" & '棲息地'!$C$2:$C995, ISNUMBER(SEARCH($B23, '棲息地'!$D$2:$D995))), 1), """")"),"華麗的桌子 / 椅子(任意) ×1、桌子(任意) ×1") -> 華麗的桌子 / 椅子(任意) ×1、桌子(任意) ×1 | I23: =IFERROR(__xludf.DUMMYFUNCTION("IFERROR(INDEX(FILTER('棲息地'!$D$2:$D995, ISNUMBER(SEARCH($B23, '棲息地'!$D$2:$D995))), 1), """")"),"口呆花、大食花") -> 口呆花、大食花 | J23: =IFERROR(__xludf.DUMMYFUNCTION("IFERROR(INDEX(FILTER('棲息地'!$B$2:$B995 & "" / "" & '棲息地'!$C$2:$C995, ISNUMBER(SEARCH($B23, '棲息地'!$D$2:$D995))), 2), """")"),"光與香氣的勾引 / 盤子上的食物 ×1") -> 光與香氣的勾引 / 盤子上的食物 ×1 | K23: =IFERROR(__xludf.DUMMYFUNCTION("IFERROR(INDEX(FILTER('棲息地'!$D$2:$D995, ISNUMBER(SEARCH($B23, '棲息地'!$D$2:$D995))), 2), """")"),"口呆花") -> 口呆花 | L23: =IFERROR(__xludf.DUMMYFUNCTION("IFERROR(INDEX(FILTER('棲息地'!$D$2:$D995, ISNUMBER(SEARCH($B23, '棲息地'!$D$2:$D995))), 3), """")"),"")
A24: 023 | B24: 大食花 | C24: 栽培、伐木 | E24: 滋潤 | F24: 感受自然、木製、感受土、五彩繽紛、花朵盛開 | G24: 苦 (馬鈴薯) | H24: =IFERROR(__xludf.DUMMYFUNCTION("IFERROR(INDEX(FILTER('棲息地'!$B$2:$B995 & "" / "" & '棲息地'!$C$2:$C995, ISNUMBER(SEARCH($B24, '棲息地'!$D$2:$D995))), 1), """")"),"華麗的桌子 / 椅子(任意) ×1、桌子(任意) ×1") -> 華麗的桌子 / 椅子(任意) ×1、桌子(任意) ×1 | I24: =IFERROR(__xludf.DUMMYFUNCTION("IFERROR(INDEX(FILTER('棲息地'!$D$2:$D995, ISNUMBER(SEARCH($B24, '棲息地'!$D$2:$D995))), 1), """")"),"口呆花、大食花") -> 口呆花、大食花 | J24: =IFERROR(__xludf.DUMMYFUNCTION("IFERROR(INDEX(FILTER('棲息地'!$B$2:$B995 & "" / "" & '棲息地'!$C$2:$C995, ISNUMBER(SEARCH($B24, '棲息地'!$D$2:$D995))), 2), """")"),"") | K24: =IFERROR(__xludf.DUMMYFUNCTION("IFERROR(INDEX(FILTER('棲息地'!$D$2:$D995, ISNUMBER(SEARCH($B24, '棲息地'!$D$2:$D995))), 2), """")"),"") | L24: =IFERROR(__xludf.DUMMYFUNCTION("IFERROR(INDEX(FILTER('棲息地'!$D$2:$D995, ISNUMBER(SEARCH($B24, '棲息地'!$D$2:$D995))), 3), """")"),"")
A25: 024 | B25: 呆呆獸 | C25: 滋潤、哈欠 | E25: 滋潤 | F25: 感受水、整潔、不可思議、柔軟、療癒傷口 | G25: 澀 (小麥) | H25: =IFERROR(__xludf.DUMMYFUNCTION("IFERROR(INDEX(FILTER('棲息地'!$B$2:$B995 & "" / "" & '棲息地'!$C$2:$C995, ISNUMBER(SEARCH($B25, '棲息地'!$D$2:$D995))), 1), """")"),"海浪邊的草叢 / 綠草 ×4、海水 ×2") -> 海浪邊的草叢 / 綠草 ×4、海水 ×2 | I25: =IFERROR(__xludf.DUMMYFUNCTION("IFERROR(INDEX(FILTER('棲息地'!$D$2:$D995, ISNUMBER(SEARCH($B25, '棲息地'!$D$2:$D995))), 1), """")"),"呆呆獸、呆呆王、呆殼獸") -> 呆呆獸、呆呆王、呆殼獸 | J25: =IFERROR(__xludf.DUMMYFUNCTION("IFERROR(INDEX(FILTER('棲息地'!$B$2:$B995 & "" / "" & '棲息地'!$C$2:$C995, ISNUMBER(SEARCH($B25, '棲息地'!$D$2:$D995))), 2), """")"),"") | K25: =IFERROR(__xludf.DUMMYFUNCTION("IFERROR(INDEX(FILTER('棲息地'!$D$2:$D995, ISNUMBER(SEARCH($B25, '棲息地'!$D$2:$D995))), 2), """")"),"") | L25: =IFERROR(__xludf.DUMMYFUNCTION("IFERROR(INDEX(FILTER('棲息地'!$D$2:$D995, ISNUMBER(SEARCH($B25, '棲息地'!$D$2:$D995))), 3), """")"),"")
A26: 025 | B26: 呆殼獸 | C26: 滋潤、交易 | E26: 滋潤 | F26: 感受水、整潔、不可思議、大家一起用、療癒傷口 | G26: 澀 (小麥) | H26: =IFERROR(__xludf.DUMMYFUNCTION("IFERROR(INDEX(FILTER('棲息地'!$B$2:$B995 & "" / "" & '棲息地'!$C$2:$C995, ISNUMBER(SEARCH($B26, '棲息地'!$D$2:$D995))), 1), """")"),"海浪邊的草叢 / 綠草 ×4、海水 ×2") -> 海浪邊的草叢 / 綠草 ×4、海水 ×2 | I26: =IFERROR(__xludf.DUMMYFUNCTION("IFERROR(INDEX(FILTER('棲息地'!$D$2:$D995, ISNUMBER(SEARCH($B26, '棲息地'!$D$2:$D995))), 1), """")"),"呆呆獸、呆呆王、呆殼獸") -> 呆呆獸、呆呆王、呆殼獸 | J26: =IFERROR(__xludf.DUMMYFUNCTION("IFERROR(INDEX(FILTER('棲息地'!$B$2:$B995 & "" / "" & '棲息地'!$C$2:$C995, ISNUMBER(SEARCH($B26, '棲息地'!$D$2:$D995))), 2), """")"),"釣魚池 / 釣竿 ×1、椅子 ×1") -> 釣魚池 / 釣竿 ×1、椅子 ×1 | K26: =IFERROR(__xludf.DUMMYFUNCTION("IFERROR(INDEX(FILTER('棲息地'!$D$2:$D995, ISNUMBER(SEARCH($B26, '棲息地'!$D$2:$D995))), 2), """")"),"呆呆王、呆殼獸") -> 呆呆王、呆殼獸 | L26: =IFERROR(__xludf.DUMMYFUNCTION("IFERROR(INDEX(FILTER('棲息地'!$D$2:$D995, ISNUMBER(SEARCH($B26, '棲息地'!$D$2:$D995))), 3), """")"),"")
A27: 026 | B27: 呆呆王 | C27: 滋潤、瞬間移動 | E27: 滋潤 | F27: 感受水、整潔、不可思議、大家一起用、療癒傷口 | G27: 酸 (番茄) | H27: =IFERROR(__xludf.DUMMYFUNCTION("IFERROR(INDEX(FILTER('棲息地'!$B$2:$B995 & "" / "" & '棲息地'!$C$2:$C995, ISNUMBER(SEARCH($B27, '棲息地'!$D$2:$D995))), 1), """")"),"海浪邊的草叢 / 綠草 ×4、海水 ×2") -> 海浪邊的草叢 / 綠草 ×4、海水 ×2 | I27: =IFERROR(__xludf.DUMMYFUNCTION("IFERROR(INDEX(FILTER('棲息地'!$D$2:$D995, ISNUMBER(SEARCH($B27, '棲息地'!$D$2:$D995))), 1), """")"),"呆呆獸、呆呆王、呆殼獸") -> 呆呆獸、呆呆王、呆殼獸 | J27: =IFERROR(__xludf.DUMMYFUNCTION("IFERROR(INDEX(FILTER('棲息地'!$B$2:$B995 & "" / "" & '棲息地'!$C$2:$C995, ISNUMBER(SEARCH($B27, '棲息地'!$D$2:$D995))), 2), """")"),"釣魚池 / 釣竿 ×1、椅子 ×1") -> 釣魚池 / 釣竿 ×1、椅子 ×1 | K27: =IFERROR(__xludf.DUMMYFUNCTION("IFERROR(INDEX(FILTER('棲息地'!$D$2:$D995, ISNUMBER(SEARCH($B27, '棲息地'!$D$2:$D995))), 2), """")"),"呆呆王、呆殼獸") -> 呆呆王、呆殼獸 | L27: =IFERROR(__xludf.DUMMYFUNCTION("IFERROR(INDEX(FILTER('棲息地'!$D$2:$D995, ISNUMBER(SEARCH($B27, '棲息地'!$D$2:$D995))), 3), """")"),"")
A28: 027 | B28: 小磁怪 | C28: 發電 | E28: 明亮 | F28: 電力驅動、金屬感、閃閃發光、堅硬、大家一起用 | G28: 苦 (馬鈴薯) | H28: =IFERROR(__xludf.DUMMYFUNCTION("IFERROR(INDEX(FILTER('棲息地'!$B$2:$B995 & "" / "" & '棲息地'!$C$2:$C995, ISNUMBER(SEARCH($B28, '棲息地'!$D$2:$D995))), 1), """")"),"工廠倉庫 / 路燈(任意) ×1") -> 工廠倉庫 / 路燈(任意) ×1 | I28: =IFERROR(__xludf.DUMMYFUNCTION("IFERROR(INDEX(FILTER('棲息地'!$D$2:$D995, ISNUMBER(SEARCH($B28, '棲息地'!$D$2:$D995))), 1), """")"),"小磁怪") -> 小磁怪 | J28: =IFERROR(__xludf.DUMMYFUNCTION("IFERROR(INDEX(FILTER('棲息地'!$B$2:$B995 & "" / "" & '棲息地'!$C$2:$C995, ISNUMBER(SEARCH($B28, '棲息地'!$D$2:$D995))), 2), """")"),"") | K28: =IFERROR(__xludf.DUMMYFUNCTION("IFERROR(INDEX(FILTER('棲息地'!$D$2:$D995, ISNUMBER(SEARCH($B28, '棲息地'!$D$2:$D995))), 2), """")"),"") | L28: =IFERROR(__xludf.DUMMYFUNCTION("IFERROR(INDEX(FILTER('棲息地'!$D$2:$D995, ISNUMBER(SEARCH($B28, '棲息地'!$D$2:$D995))), 3), """")"),"")
A29: 028 | B29: 三合一磁怪 | C29: 發電 | E29: 明亮 | F29: 電力驅動、金屬感、閃閃發光、聚集、大家一起用 | G29: 苦 (馬鈴薯) | H29: =IFERROR(__xludf.DUMMYFUNCTION("IFERROR(INDEX(FILTER('棲息地'!$B$2:$B995 & "" / "" & '棲息地'!$C$2:$C995, ISNUMBER(SEARCH($B29, '棲息地'!$D$2:$D995))), 1), """")"),"垃圾桶擺好擺滿 / 垃圾桶 ×4") -> 垃圾桶擺好擺滿 / 垃圾桶 ×4 | I29: =IFERROR(__xludf.DUMMYFUNCTION("IFERROR(INDEX(FILTER('棲息地'!$D$2:$D995, ISNUMBER(SEARCH($B29, '棲息地'!$D$2:$D995))), 1), """")"),"三合一磁怪、電擊獸") -> 三合一磁怪、電擊獸 | J29: =IFERROR(__xludf.DUMMYFUNCTION("IFERROR(INDEX(FILTER('棲息地'!$B$2:$B995 & "" / "" & '棲息地'!$C$2:$C995, ISNUMBER(SEARCH($B29, '棲息地'!$D$2:$D995))), 2), """")"),"迷你遊戲城 / 椅子 ×1、遊戲街機 ×1、打擊測力機 ×1") -> 迷你遊戲城 / 椅子 ×1、遊戲街機 ×1、打擊測力機 ×1 | K29: =IFERROR(__xludf.DUMMYFUNCTION("IFERROR(INDEX(FILTER('棲息地'!$D$2:$D995, ISNUMBER(SEARCH($B29, '棲息地'!$D$2:$D995))), 2), """")"),"三合一磁怪（★）、自爆磁怪（★★）") -> 三合一磁怪（★）、自爆磁怪（★★） | L29: =IFERROR(__xludf.DUMMYFUNCTION("IFERROR(INDEX(FILTER('棲息地'!$D$2:$D995, ISNUMBER(SEARCH($B29, '棲息地'!$D$2:$D995))), 3), """")"),"")
A30: 029 | B30: 自爆磁怪 | C30: 回收利用、發電 | E30: 明亮 | F30: 電力驅動、金屬感、華麗、聚集、堅硬 | G30: 苦 (馬鈴薯) | H30: =IFERROR(__xludf.DUMMYFUNCTION("IFERROR(INDEX(FILTER('棲息地'!$B$2:$B995 & "" / "" & '棲息地'!$C$2:$C995, ISNUMBER(SEARCH($B30, '棲息地'!$D$2:$D995))), 1), """")"),"迷你遊戲城 / 椅子 ×1、遊戲街機 ×1、打擊測力機 ×1") -> 迷你遊戲城 / 椅子 ×1、遊戲街機 ×1、打擊測力機 ×1 | I30: =IFERROR(__xludf.DUMMYFUNCTION("IFERROR(INDEX(FILTER('棲息地'!$D$2:$D995, ISNUMBER(SEARCH($B30, '棲息地'!$D$2:$D995))), 1), """")"),"三合一磁怪（★）、自爆磁怪（★★）") -> 三合一磁怪（★）、自爆磁怪（★★） | J30: =IFERROR(__xludf.DUMMYFUNCTION("IFERROR(INDEX(FILTER('棲息地'!$B$2:$B995 & "" / "" & '棲息地'!$C$2:$C995, ISNUMBER(SEARCH($B30, '棲息地'!$D$2:$D995))), 2), """")"),"") | K30: =IFERROR(__xludf.DUMMYFUNCTION("IFERROR(INDEX(FILTER('棲息地'!$D$2:$D995, ISNUMBER(SEARCH($B30, '棲息地'!$D$2:$D995))), 2), """")"),"") | L30: =IFERROR(__xludf.DUMMYFUNCTION("IFERROR(INDEX(FILTER('棲息地'!$D$2:$D995, ISNUMBER(SEARCH($B30, '棲息地'!$D$2:$D995))), 3), """")"),"")
A31: 030 | B31: 大岩蛇 | C31: 碾壓、重踏 | E31: 乾燥 | F31: 石造、感受土、方形、細長、訓練 | G31: 澀 (小麥) | H31: =IFERROR(__xludf.DUMMYFUNCTION("IFERROR(INDEX(FILTER('棲息地'!$B$2:$B995 & "" / "" & '棲息地'!$C$2:$C995, ISNUMBER(SEARCH($B31, '棲息地'!$D$2:$D995))), 1), """")"),"乾爽草叢 / 枯萎的綠草 ×4、沙沙岩石 ×1") -> 乾爽草叢 / 枯萎的綠草 ×4、沙沙岩石 ×1 | I31: =IFERROR(__xludf.DUMMYFUNCTION("IFERROR(INDEX(FILTER('棲息地'!$D$2:$D995, ISNUMBER(SEARCH($B31, '棲息地'!$D$2:$D995))), 1), """")"),"大岩蛇") -> 大岩蛇 | J31: =IFERROR(__xludf.DUMMYFUNCTION("IFERROR(INDEX(FILTER('棲息地'!$B$2:$B995 & "" / "" & '棲息地'!$C$2:$C995, ISNUMBER(SEARCH($B31, '棲息地'!$D$2:$D995))), 2), """")"),"") | K31: =IFERROR(__xludf.DUMMYFUNCTION("IFERROR(INDEX(FILTER('棲息地'!$D$2:$D995, ISNUMBER(SEARCH($B31, '棲息地'!$D$2:$D995))), 2), """")"),"") | L31: =IFERROR(__xludf.DUMMYFUNCTION("IFERROR(INDEX(FILTER('棲息地'!$D$2:$D995, ISNUMBER(SEARCH($B31, '棲息地'!$D$2:$D995))), 3), """")"),"")
A32: 031 | B32: 大鋼蛇 | C32: 碾壓、重踏 | E32: 乾燥 | F32: 金屬感、感受土、石造、細長、堅硬 | G32: 酸 (番茄) | H32: =IFERROR(__xludf.DUMMYFUNCTION("IFERROR(INDEX(FILTER('棲息地'!$B$2:$B995 & "" / "" & '棲息地'!$C$2:$C995, ISNUMBER(SEARCH($B32, '棲息地'!$D$2:$D995))), 1), """")"),"鏘啷鏘啷鋼構工程 / 獨輪手推車 ×1、沙包袋 ×1、挖礦工具 ×1") -> 鏘啷鏘啷鋼構工程 / 獨輪手推車 ×1、沙包袋 ×1、挖礦工具 ×1 | I32: =IFERROR(__xludf.DUMMYFUNCTION("IFERROR(INDEX(FILTER('棲息地'!$D$2:$D995, ISNUMBER(SEARCH($B32, '棲息地'!$D$2:$D995))), 1), """")"),"大鋼蛇") -> 大鋼蛇 | J32: =IFERROR(__xludf.DUMMYFUNCTION("IFERROR(INDEX(FILTER('棲息地'!$B$2:$B995 & "" / "" & '棲息地'!$C$2:$C995, ISNUMBER(SEARCH($B32, '棲息地'!$D$2:$D995))), 2), """")"),"") | K32: =IFERROR(__xludf.DUMMYFUNCTION("IFERROR(INDEX(FILTER('棲息地'!$D$2:$D995, ISNUMBER(SEARCH($B32, '棲息地'!$D$2:$D995))), 2), """")"),"") | L32: =IFERROR(__xludf.DUMMYFUNCTION("IFERROR(INDEX(FILTER('棲息地'!$D$2:$D995, ISNUMBER(SEARCH($B32, '棲息地'!$D$2:$D995))), 3), """")"),"")
A33: 032 | B33: 卡拉卡拉 | C33: 建造 | E33: 乾燥 | F33: 感受土、建設、訓練、細長、大家一起用 | G33: 苦 (馬鈴薯) | H33: =IFERROR(__xludf.DUMMYFUNCTION("IFERROR(INDEX(FILTER('棲息地'!$B$2:$B995 & "" / "" & '棲息地'!$C$2:$C995, ISNUMBER(SEARCH($B33, '棲息地'!$D$2:$D995))), 1), """")"),"花朵纏繞的墓地 / 原野之花 ×4、墓碑 ×1") -> 花朵纏繞的墓地 / 原野之花 ×4、墓碑 ×1 | I33: =IFERROR(__xludf.DUMMYFUNCTION("IFERROR(INDEX(FILTER('棲息地'!$D$2:$D995, ISNUMBER(SEARCH($B33, '棲息地'!$D$2:$D995))), 1), """")"),"卡拉卡拉、嘎啦嘎啦") -> 卡拉卡拉、嘎啦嘎啦 | J33: =IFERROR(__xludf.DUMMYFUNCTION("IFERROR(INDEX(FILTER('棲息地'!$B$2:$B995 & "" / "" & '棲息地'!$C$2:$C995, ISNUMBER(SEARCH($B33, '棲息地'!$D$2:$D995))), 2), """")"),"") | K33: =IFERROR(__xludf.DUMMYFUNCTION("IFERROR(INDEX(FILTER('棲息地'!$D$2:$D995, ISNUMBER(SEARCH($B33, '棲息地'!$D$2:$D995))), 2), """")"),"") | L33: =IFERROR(__xludf.DUMMYFUNCTION("IFERROR(INDEX(FILTER('棲息地'!$D$2:$D995, ISNUMBER(SEARCH($B33, '棲息地'!$D$2:$D995))), 3), """")"),"")
A34: 033 | B34: 嘎啦嘎啦 | C34: 建造 | E34: 乾燥 | F34: 感受土、建設、訓練、細長、華麗 | G34: 澀 (小麥) | H34: =IFERROR(__xludf.DUMMYFUNCTION("IFERROR(INDEX(FILTER('棲息地'!$B$2:$B995 & "" / "" & '棲息地'!$C$2:$C995, ISNUMBER(SEARCH($B34, '棲息地'!$D$2:$D995))), 1), """")"),"花朵纏繞的墓地 / 原野之花 ×4、墓碑 ×1") -> 花朵纏繞的墓地 / 原野之花 ×4、墓碑 ×1 | I34: =IFERROR(__xludf.DUMMYFUNCTION("IFERROR(INDEX(FILTER('棲息地'!$D$2:$D995, ISNUMBER(SEARCH($B34, '棲息地'!$D$2:$D995))), 1), """")"),"卡拉卡拉、嘎啦嘎啦") -> 卡拉卡拉、嘎啦嘎啦 | J34: =IFERROR(__xludf.DUMMYFUNCTION("IFERROR(INDEX(FILTER('棲息地'!$B$2:$B995 & "" / "" & '棲息地'!$C$2:$C995, ISNUMBER(SEARCH($B34, '棲息地'!$D$2:$D995))), 2), """")"),"") | K34: =IFERROR(__xludf.DUMMYFUNCTION("IFERROR(INDEX(FILTER('棲息地'!$D$2:$D995, ISNUMBER(SEARCH($B34, '棲息地'!$D$2:$D995))), 2), """")"),"") | L34: =IFERROR(__xludf.DUMMYFUNCTION("IFERROR(INDEX(FILTER('棲息地'!$D$2:$D995, ISNUMBER(SEARCH($B34, '棲息地'!$D$2:$D995))), 3), """")"),"")
A35: 034 | B35: 無畏小子 | C35: 交易 | E35: 明亮 | F35: 訓練、大家一起用、布製、石造、圓形 | G35: 辣 (紅蘿蔔) | H35: =IFERROR(__xludf.DUMMYFUNCTION("IFERROR(INDEX(FILTER('棲息地'!$B$2:$B995 & "" / "" & '棲息地'!$C$2:$C995, ISNUMBER(SEARCH($B35, '棲息地'!$D$2:$D995))), 1), """")"),"修行瀑布 / 椅子(任意) ×1、水 ×2、瀑布 ×1") -> 修行瀑布 / 椅子(任意) ×1、水 ×2、瀑布 ×1 | I35: =IFERROR(__xludf.DUMMYFUNCTION("IFERROR(INDEX(FILTER('棲息地'!$D$2:$D995, ISNUMBER(SEARCH($B35, '棲息地'!$D$2:$D995))), 1), """")"),"無畏小子") -> 無畏小子 | J35: =IFERROR(__xludf.DUMMYFUNCTION("IFERROR(INDEX(FILTER('棲息地'!$B$2:$B995 & "" / "" & '棲息地'!$C$2:$C995, ISNUMBER(SEARCH($B35, '棲息地'!$D$2:$D995))), 2), """")"),"") | K35: =IFERROR(__xludf.DUMMYFUNCTION("IFERROR(INDEX(FILTER('棲息地'!$D$2:$D995, ISNUMBER(SEARCH($B35, '棲息地'!$D$2:$D995))), 2), """")"),"") | L35: =IFERROR(__xludf.DUMMYFUNCTION("IFERROR(INDEX(FILTER('棲息地'!$D$2:$D995, ISNUMBER(SEARCH($B35, '棲息地'!$D$2:$D995))), 3), """")"),"")
A36: 035 | B36: 飛腿郎 | C36: 交易 | E36: 明亮 | F36: 訓練、大家一起用、布製、石造、圓形 | G36: 辣 (紅蘿蔔) | H36: =IFERROR(__xludf.DUMMYFUNCTION("IFERROR(INDEX(FILTER('棲息地'!$B$2:$B995 & "" / "" & '棲息地'!$C$2:$C995, ISNUMBER(SEARCH($B36, '棲息地'!$D$2:$D995))), 1), """")"),"緊急救護站 / 椅子(任意) ×1、桌子(任意) ×1、急救箱 ×1") -> 緊急救護站 / 椅子(任意) ×1、桌子(任意) ×1、急救箱 ×1 | I36: =IFERROR(__xludf.DUMMYFUNCTION("IFERROR(INDEX(FILTER('棲息地'!$D$2:$D995, ISNUMBER(SEARCH($B36, '棲息地'!$D$2:$D995))), 1), """")"),"飛腿郎") -> 飛腿郎 | J36: =IFERROR(__xludf.DUMMYFUNCTION("IFERROR(INDEX(FILTER('棲息地'!$B$2:$B995 & "" / "" & '棲息地'!$C$2:$C995, ISNUMBER(SEARCH($B36, '棲息地'!$D$2:$D995))), 2), """")"),"") | K36: =IFERROR(__xludf.DUMMYFUNCTION("IFERROR(INDEX(FILTER('棲息地'!$D$2:$D995, ISNUMBER(SEARCH($B36, '棲息地'!$D$2:$D995))), 2), """")"),"") | L36: =IFERROR(__xludf.DUMMYFUNCTION("IFERROR(INDEX(FILTER('棲息地'!$D$2:$D995, ISNUMBER(SEARCH($B36, '棲息地'!$D$2:$D995))), 3), """")"),"")
A37: 036 | B37: 快拳郎 | C37: 交易 | E37: 明亮 | F37: 訓練、大家一起用、布製、石造、圓形 | G37: 甜 (桃桃果) | H37: =IFERROR(__xludf.DUMMYFUNCTION("IFERROR(INDEX(FILTER('棲息地'!$B$2:$B995 & "" / "" & '棲息地'!$C$2:$C995, ISNUMBER(SEARCH($B37, '棲息地'!$D$2:$D995))), 1), """")"),"健身區用餐區 / 沙包 ×1、椅子(任意) ×1") -> 健身區用餐區 / 沙包 ×1、椅子(任意) ×1 | I37: =IFERROR(__xludf.DUMMYFUNCTION("IFERROR(INDEX(FILTER('棲息地'!$D$2:$D995, ISNUMBER(SEARCH($B37, '棲息地'!$D$2:$D995))), 1), """")"),"快拳郎") -> 快拳郎 | J37: =IFERROR(__xludf.DUMMYFUNCTION("IFERROR(INDEX(FILTER('棲息地'!$B$2:$B995 & "" / "" & '棲息地'!$C$2:$C995, ISNUMBER(SEARCH($B37, '棲息地'!$D$2:$D995))), 2), """")"),"") | K37: =IFERROR(__xludf.DUMMYFUNCTION("IFERROR(INDEX(FILTER('棲息地'!$D$2:$D995, ISNUMBER(SEARCH($B37, '棲息地'!$D$2:$D995))), 2), """")"),"") | L37: =IFERROR(__xludf.DUMMYFUNCTION("IFERROR(INDEX(FILTER('棲息地'!$D$2:$D995, ISNUMBER(SEARCH($B37, '棲息地'!$D$2:$D995))), 3), """")"),"")
A38: 037 | B38: 戰舞郎 | C38: 交易 | E38: 明亮 | F38: 訓練、大家一起用、布製、石造、圓形 | G38: 甜 (桃桃果) | H38: =IFERROR(__xludf.DUMMYFUNCTION("IFERROR(INDEX(FILTER('棲息地'!$B$2:$B995 & "" / "" & '棲息地'!$C$2:$C995, ISNUMBER(SEARCH($B38, '棲息地'!$D$2:$D995))), 1), """")"),"健身區救護站 / 桌子(任意) ×1、沙包 ×1、急救箱 ×1") -> 健身區救護站 / 桌子(任意) ×1、沙包 ×1、急救箱 ×1 | I38: =IFERROR(__xludf.DUMMYFUNCTION("IFERROR(INDEX(FILTER('棲息地'!$D$2:$D995, ISNUMBER(SEARCH($B38, '棲息地'!$D$2:$D995))), 1), """")"),"戰舞郎") -> 戰舞郎 | J38: =IFERROR(__xludf.DUMMYFUNCTION("IFERROR(INDEX(FILTER('棲息地'!$B$2:$B995 & "" / "" & '棲息地'!$C$2:$C995, ISNUMBER(SEARCH($B38, '棲息地'!$D$2:$D995))), 2), """")"),"") | K38: =IFERROR(__xludf.DUMMYFUNCTION("IFERROR(INDEX(FILTER('棲息地'!$D$2:$D995, ISNUMBER(SEARCH($B38, '棲息地'!$D$2:$D995))), 2), """")"),"") | L38: =IFERROR(__xludf.DUMMYFUNCTION("IFERROR(INDEX(FILTER('棲息地'!$D$2:$D995, ISNUMBER(SEARCH($B38, '棲息地'!$D$2:$D995))), 3), """")"),"")
A39: 038 | B39: 瓦斯彈 | C39: 回收利用 | E39: 昏暗 | F39: 垃圾、聚集、看起來很難、柔軟、搖晃 | G39: 苦 (馬鈴薯) | H39: =IFERROR(__xludf.DUMMYFUNCTION("IFERROR(INDEX(FILTER('棲息地'!$B$2:$B995 & "" / "" & '棲息地'!$C$2:$C995, ISNUMBER(SEARCH($B39, '棲息地'!$D$2:$D995))), 1), """")"),"垃圾集中站 / 垃圾桶 ×1、告示牌 ×1、垃圾袋 ×1") -> 垃圾集中站 / 垃圾桶 ×1、告示牌 ×1、垃圾袋 ×1 | I39: =IFERROR(__xludf.DUMMYFUNCTION("IFERROR(INDEX(FILTER('棲息地'!$D$2:$D995, ISNUMBER(SEARCH($B39, '棲息地'!$D$2:$D995))), 1), """")"),"破破袋、瓦斯彈（空空鎮)、雙彈瓦斯（空空鎮)、灰塵山") -> 破破袋、瓦斯彈（空空鎮)、雙彈瓦斯（空空鎮)、灰塵山 | J39: =IFERROR(__xludf.DUMMYFUNCTION("IFERROR(INDEX(FILTER('棲息地'!$B$2:$B995 & "" / "" & '棲息地'!$C$2:$C995, ISNUMBER(SEARCH($B39, '棲息地'!$D$2:$D995))), 2), """")"),"") | K39: =IFERROR(__xludf.DUMMYFUNCTION("IFERROR(INDEX(FILTER('棲息地'!$D$2:$D995, ISNUMBER(SEARCH($B39, '棲息地'!$D$2:$D995))), 2), """")"),"") | L39: =IFERROR(__xludf.DUMMYFUNCTION("IFERROR(INDEX(FILTER('棲息地'!$D$2:$D995, ISNUMBER(SEARCH($B39, '棲息地'!$D$2:$D995))), 3), """")"),"")
A40: 039 | B40: 雙彈瓦斯 | C40: 回收利用 | E40: 昏暗 | F40: 垃圾、聚集、看起來很難、柔軟、搖晃 | G40: 苦 (馬鈴薯) | H40: =IFERROR(__xludf.DUMMYFUNCTION("IFERROR(INDEX(FILTER('棲息地'!$B$2:$B995 & "" / "" & '棲息地'!$C$2:$C995, ISNUMBER(SEARCH($B40, '棲息地'!$D$2:$D995))), 1), """")"),"懷舊古董 / 古董衣櫃/床鋪/梳妝台/椅子 各1") -> 懷舊古董 / 古董衣櫃/床鋪/梳妝台/椅子 各1 | I40: =IFERROR(__xludf.DUMMYFUNCTION("IFERROR(INDEX(FILTER('棲息地'!$D$2:$D995, ISNUMBER(SEARCH($B40, '棲息地'!$D$2:$D995))), 1), """")"),"雙彈瓦斯（★）、卡比獸（★）") -> 雙彈瓦斯（★）、卡比獸（★） | J40: =IFERROR(__xludf.DUMMYFUNCTION("IFERROR(INDEX(FILTER('棲息地'!$B$2:$B995 & "" / "" & '棲息地'!$C$2:$C995, ISNUMBER(SEARCH($B40, '棲息地'!$D$2:$D995))), 2), """")"),"垃圾集中站 / 垃圾桶 ×1、告示牌 ×1、垃圾袋 ×1") -> 垃圾集中站 / 垃圾桶 ×1、告示牌 ×1、垃圾袋 ×1 | K40: =IFERROR(__xludf.DUMMYFUNCTION("IFERROR(INDEX(FILTER('棲息地'!$D$2:$D995, ISNUMBER(SEARCH($B40, '棲息地'!$D$2:$D995))), 2), """")"),"破破袋、瓦斯彈（空空鎮)、雙彈瓦斯（空空鎮)、灰塵山") -> 破破袋、瓦斯彈（空空鎮)、雙彈瓦斯（空空鎮)、灰塵山 | L40: =IFERROR(__xludf.DUMMYFUNCTION("IFERROR(INDEX(FILTER('棲息地'!$D$2:$D995, ISNUMBER(SEARCH($B40, '棲息地'!$D$2:$D995))), 3), """")"),"")
...
